Workbook

Sheet Read me
A1: F1 canon register v2 — full coverage at zero cost
A2: Built 2026-09-28. Companion to the doc 'F1 Scope v2 — everything, at zero cost'.
A4: What this is
A5: Every grouping, technique, material, object type, living practice and 'first known' claim F1's Atlas should hold, so nothing a learner might look for is missing. 4,228 nodes in 24 kinds (round 2 added communities, people, places, events, periods and the blind-map additions), plus 198 zero-cost source routes and 130 primary texts.
A6: Tiers
A7: R1 = taught in a unit, full grouping page with an authored walk. R2 = card and member grid (needs 5+ verified members and a source). R3 = card and link out. Every node gets at least R3; promotion is by evidence, not fame.
A8: How it was checked
A9: Drafted from knowledge in six parallel passes, then fact-checked independently: every R1 row, every low/medium-confidence R1/R2 row, every UNESCO claim, and random samples (about 620 rows). 66 rows corrected; logs in REVIEW_LOG_people.md and REVIEW_LOG_things.md. Random-sample error rate 1 in 120; UNESCO statuses written from memory were wrong 19 times in 124, so UNESCO status must be harvested from the ICH dataset, never typed. Round 2 (29 September): about 680 more rows checked (people, places, events, periods, communities, blind-map additions) and 106 corrected; priority rows (R1/R2, living people, UNESCO claims, endonyms) erred at 8–14%, random samples at 0–8%. Logs: REVIEW_LOG_round2_*.md.
A10: Not yet done
A11: No Wikidata/Getty/PeriodO identifiers are included on purpose (none were guessed); the harvest matches them. Rows at confidence 'low' or 'medium' outside R1 are unverified drafts.
A12: Sheets
A13: Summary — counts by kind and tier (formulas). Canon — all nodes, one row each, filterable. Coverage grid — nodes per sub-region and period band (formulas; recalculates as rows change). Functions x worlds — object types per function per world. Sources — zero-cost routes with licence and commercial-safe flag. Primary texts — texts on making, with public-domain status.
... A15: Sub-regions: 46 codes (AF-, AM-, AS-, WA-, EU-, OC-, GL). Period bands B01–B11. Worlds: F1.6 Africa · F1.7 Americas · F1.8 East Asia · F1.9 South and Southeast Asia · F1.9a West Asia before Islam · F1.10 Islamic world · F1.11 Europe and the Mediterranean · F1.12 Australia and the Pacific · F1.12a Steppe and Central Asia · F1.13 Networks · THEME.

Sheet Summary
A1: Kind | B1: R1 | C1: R2 | D1: R3 | E1: Total
A2: person | B2: =COUNTIFS(Canon!$D$2:$D$4229,$A2,Canon!$S$2:$S$4229,"R1") -> 5 | C2: =COUNTIFS(Canon!$D$2:$D$4229,$A2,Canon!$S$2:$S$4229,"R2") -> 25 | D2: =COUNTIFS(Canon!$D$2:$D$4229,$A2,Canon!$S$2:$S$4229,"R3") -> 450 | E2: =SUM(B2:D2) -> 480
A3: place | B3: =COUNTIFS(Canon!$D$2:$D$4229,$A3,Canon!$S$2:$S$4229,"R1") -> 22 | C3: =COUNTIFS(Canon!$D$2:$D$4229,$A3,Canon!$S$2:$S$4229,"R2") -> 144 | D3: =COUNTIFS(Canon!$D$2:$D$4229,$A3,Canon!$S$2:$S$4229,"R3") -> 253 | E3: =SUM(B3:D3) -> 419
A4: object-type | B4: =COUNTIFS(Canon!$D$2:$D$4229,$A4,Canon!$S$2:$S$4229,"R1") -> 31 | C4: =COUNTIFS(Canon!$D$2:$D$4229,$A4,Canon!$S$2:$S$4229,"R2") -> 155 | D4: =COUNTIFS(Canon!$D$2:$D$4229,$A4,Canon!$S$2:$S$4229,"R3") -> 172 | E4: =SUM(B4:D4) -> 358
A5: event | B5: =COUNTIFS(Canon!$D$2:$D$4229,$A5,Canon!$S$2:$S$4229,"R1") -> 14 | C5: =COUNTIFS(Canon!$D$2:$D$4229,$A5,Canon!$S$2:$S$4229,"R2") -> 107 | D5: =COUNTIFS(Canon!$D$2:$D$4229,$A5,Canon!$S$2:$S$4229,"R3") -> 207 | E5: =SUM(B5:D5) -> 328
A6: community | B6: =COUNTIFS(Canon!$D$2:$D$4229,$A6,Canon!$S$2:$S$4229,"R1") -> 19 | C6: =COUNTIFS(Canon!$D$2:$D$4229,$A6,Canon!$S$2:$S$4229,"R2") -> 96 | D6: =COUNTIFS(Canon!$D$2:$D$4229,$A6,Canon!$S$2:$S$4229,"R3") -> 185 | E6: =SUM(B6:D6) -> 300
A7: polity | B7: =COUNTIFS(Canon!$D$2:$D$4229,$A7,Canon!$S$2:$S$4229,"R1") -> 50 | C7: =COUNTIFS(Canon!$D$2:$D$4229,$A7,Canon!$S$2:$S$4229,"R2") -> 145 | D7: =COUNTIFS(Canon!$D$2:$D$4229,$A7,Canon!$S$2:$S$4229,"R3") -> 45 | E7: =SUM(B7:D7) -> 240
A8: technique | B8: =COUNTIFS(Canon!$D$2:$D$4229,$A8,Canon!$S$2:$S$4229,"R1") -> 13 | C8: =COUNTIFS(Canon!$D$2:$D$4229,$A8,Canon!$S$2:$S$4229,"R2") -> 51 | D8: =COUNTIFS(Canon!$D$2:$D$4229,$A8,Canon!$S$2:$S$4229,"R3") -> 173 | E8: =SUM(B8:D8) -> 237
A9: archaeological-culture | B9: =COUNTIFS(Canon!$D$2:$D$4229,$A9,Canon!$S$2:$S$4229,"R1") -> 4 | C9: =COUNTIFS(Canon!$D$2:$D$4229,$A9,Canon!$S$2:$S$4229,"R2") -> 54 | D9: =COUNTIFS(Canon!$D$2:$D$4229,$A9,Canon!$S$2:$S$4229,"R3") -> 172 | E9: =SUM(B9:D9) -> 230
A10: period | B10: =COUNTIFS(Canon!$D$2:$D$4229,$A10,Canon!$S$2:$S$4229,"R1") -> 5 | C10: =COUNTIFS(Canon!$D$2:$D$4229,$A10,Canon!$S$2:$S$4229,"R2") -> 50 | D10: =COUNTIFS(Canon!$D$2:$D$4229,$A10,Canon!$S$2:$S$4229,"R3") -> 165 | E10: =SUM(B10:D10) -> 220
A11: living-practice | B11: =COUNTIFS(Canon!$D$2:$D$4229,$A11,Canon!$S$2:$S$4229,"R1") -> 17 | C11: =COUNTIFS(Canon!$D$2:$D$4229,$A11,Canon!$S$2:$S$4229,"R2") -> 94 | D11: =COUNTIFS(Canon!$D$2:$D$4229,$A11,Canon!$S$2:$S$4229,"R3") -> 103 | E11: =SUM(B11:D11) -> 214
A12: style | B12: =COUNTIFS(Canon!$D$2:$D$4229,$A12,Canon!$S$2:$S$4229,"R1") -> 9 | C12: =COUNTIFS(Canon!$D$2:$D$4229,$A12,Canon!$S$2:$S$4229,"R2") -> 66 | D12: =COUNTIFS(Canon!$D$2:$D$4229,$A12,Canon!$S$2:$S$4229,"R3") -> 120 | E12: =SUM(B12:D12) -> 195
A13: first-known | B13: =COUNTIFS(Canon!$D$2:$D$4229,$A13,Canon!$S$2:$S$4229,"R1") -> 22 | C13: =COUNTIFS(Canon!$D$2:$D$4229,$A13,Canon!$S$2:$S$4229,"R2") -> 70 | D13: =COUNTIFS(Canon!$D$2:$D$4229,$A13,Canon!$S$2:$S$4229,"R3") -> 82 | E13: =SUM(B13:D13) -> 174
... A25: interaction-sphere | B25: =COUNTIFS(Canon!$D$2:$D$4229,$A25,Canon!$S$2:$S$4229,"R1") -> 0 | C25: =COUNTIFS(Canon!$D$2:$D$4229,$A25,Canon!$S$2:$S$4229,"R2") -> 3 | D25: =COUNTIFS(Canon!$D$2:$D$4229,$A25,Canon!$S$2:$S$4229,"R3") -> 0 | E25: =SUM(B25:D25) -> 3
A26: All kinds | B26: =SUM(B2:B25) -> 269 | C26: =SUM(C2:C25) -> 1268 | D26: =SUM(D2:D25) -> 2691 | E26: =SUM(E2:E25) -> 4228

Sheet Coverage grid
A1: Nodes per sub-region and period band (a node counts in every band its date range touches). 0 = gap, or no people there yet (see note column). Band edges are in rows 3–4 and drive the formulas.
B3: band start | C3: -9999999 | D3: -8000 | E3: -4000 | F3: -2000 | G3: -1000 | H3: 1 | I3: 500 | J3: 1000 | K3: 1400 | L3: 1700 | M3: 1900
B4: band end | C4: -8000 | D4: -4000 | E4: -2000 | F4: -1000 | G4: 1 | H4: 500 | I4: 1000 | J4: 1400 | K4: 1700 | L4: 1900 | M4: 2027
A5: Code | B5: Sub-region | C5: B01 before 8000 BCE | D5: B02 8000–4000 BCE | E5: B03 4000–2000 BCE | F5: B04 2000–1000 BCE | G5: B05 1000 BCE–1 CE | H5: B06 1–500 | I5: B07 500–1000 | J5: B08 1000–1400 | K5: B09 1400–1700 | L5: B10 1700–1900 | M5: B11 1900–now | N5: Note
A6: AF-EGY | B6: Egypt | C6: =COUNTIFS(Canon!$G$2:$G$4229,"*"&$A6&"*",Canon!$H$2:$H$4229,"<"&C$4,Canon!$I$2:$I$4229,">="&C$3)+COUNTIFS(Canon!$G$2:$G$4229,"*"&$A6&"*",Canon!$H$2:$H$4229,"<"&C$4,Canon!$I$2:$I$4229,"") -> 4 | D6: =COUNTIFS(Canon!$G$2:$G$4229,"*"&$A6&"*",Canon!$H$2:$H$4229,"<"&D$4,Canon!$I$2:$I$4229,">="&D$3)+COUNTIFS(Canon!$G$2:$G$4229,"*"&$A6&"*",Canon!$H$2:$H$4229,"<"&D$4,Canon!$I$2:$I$4229,"") -> 10 | E6: =COUNTIFS(Canon!$G$2:$G$4229,"*"&$A6&"*",Canon!$H$2:$H$4229,"<"&E$4,Canon!$I$2:$I$4229,">="&E$3)+COUNTIFS(Canon!$G$2:$G$4229,"*"&$A6&"*",Canon!$H$2:$H$4229,"<"&E$4,Canon!$I$2:$I$4229,"") -> 67 | F6: =COUNTIFS(Canon!$G$2:$G$4229,"*"&$A6&"*",Canon!$H$2:$H$4229,"<"&F$4,Canon!$I$2:$I$4229,">="&F$3)+COUNTIFS(Canon!$G$2:$G$4229,"*"&$A6&"*",Canon!$H$2:$H$4229,"<"&F$4,Canon!$I$2:$I$4229,"") -> 86 | G6: =COUNTIFS(Canon!$G$2:$G$4229,"*"&$A6&"*",Canon!$H$2:$H$4229,"<"&G$4,Canon!$I$2:$I$4229,">="&G$3)+COUNTIFS(Canon!$G$2:$G$4229,"*"&$A6&"*",Canon!$H$2:$H$4229,"<"&G$4,Canon!$I$2:$I$4229,"") -> 92 | H6: =COUNTIFS(Canon!$G$2:$G$4229,"*"&$A6&"*",Canon!$H$2:$H$4229,"<"&H$4,Canon!$I$2:$I$4229,">="&H$3)+COUNTIFS(Canon!$G$2:$G$4229,"*"&$A6&"*",Canon!$H$2:$H$4229,"<"&H$4,Canon!$I$2:$I$4229,"") -> 91 | I6: =COUNTIFS(Canon!$G$2:$G$4229,"*"&$A6&"*",Canon!$H$2:$H$4229,"<"&I$4,Canon!$I$2:$I$4229,">="&I$3)+COUNTIFS(Canon!$G$2:$G$4229,"*"&$A6&"*",Canon!$H$2:$H$4229,"<"&I$4,Canon!$I$2:$I$4229,"") -> 97 | J6: =COUNTIFS(Canon!$G$2:$G$4229,"*"&$A6&"*",Canon!$H$2:$H$4229,"<"&J$4,Canon!$I$2:$I$4229,">="&J$3)+COUNTIFS(Canon!$G$2:$G$4229,"*"&$A6&"*",Canon!$H$2:$H$4229,"<"&J$4,Canon!$I$2:$I$4229,"") -> 101 | ... M6: =COUNTIFS(Canon!$G$2:$G$4229,"*"&$A6&"*",Canon!$H$2:$H$4229,"<"&M$4,Canon!$I$2:$I$4229,">="&M$3)+COUNTIFS(Canon!$G$2:$G$4229,"*"&$A6&"*",Canon!$H$2:$H$4229,"<"&M$4,Canon!$I$2:$I$4229,"") -> 94
A7: AF-NUB | B7: Nubia and Sudan | C7: =COUNTIFS(Canon!$G$2:$G$4229,"*"&$A7&"*",Canon!$H$2:$H$4229,"<"&C$4,Canon!$I$2:$I$4229,">="&C$3)+COUNTIFS(Canon!$G$2:$G$4229,"*"&$A7&"*",Canon!$H$2:$H$4229,"<"&C$4,Canon!$I$2:$I$4229,"") -> 1 | D7: =COUNTIFS(Canon!$G$2:$G$4229,"*"&$A7&"*",Canon!$H$2:$H$4229,"<"&D$4,Canon!$I$2:$I$4229,">="&D$3)+COUNTIFS(Canon!$G$2:$G$4229,"*"&$A7&"*",Canon!$H$2:$H$4229,"<"&D$4,Canon!$I$2:$I$4229,"") -> 3 | E7: =COUNTIFS(Canon!$G$2:$G$4229,"*"&$A7&"*",Canon!$H$2:$H$4229,"<"&E$4,Canon!$I$2:$I$4229,">="&E$3)+COUNTIFS(Canon!$G$2:$G$4229,"*"&$A7&"*",Canon!$H$2:$H$4229,"<"&E$4,Canon!$I$2:$I$4229,"") -> 16 | F7: =COUNTIFS(Canon!$G$2:$G$4229,"*"&$A7&"*",Canon!$H$2:$H$4229,"<"&F$4,Canon!$I$2:$I$4229,">="&F$3)+COUNTIFS(Canon!$G$2:$G$4229,"*"&$A7&"*",Canon!$H$2:$H$4229,"<"&F$4,Canon!$I$2:$I$4229,"") -> 21 | G7: =COUNTIFS(Canon!$G$2:$G$4229,"*"&$A7&"*",Canon!$H$2:$H$4229,"<"&G$4,Canon!$I$2:$I$4229,">="&G$3)+COUNTIFS(Canon!$G$2:$G$4229,"*"&$A7&"*",Canon!$H$2:$H$4229,"<"&G$4,Canon!$I$2:$I$4229,"") -> 21 | H7: =COUNTIFS(Canon!$G$2:$G$4229,"*"&$A7&"*",Canon!$H$2:$H$4229,"<"&H$4,Canon!$I$2:$I$4229,">="&H$3)+COUNTIFS(Canon!$G$2:$G$4229,"*"&$A7&"*",Canon!$H$2:$H$4229,"<"&H$4,Canon!$I$2:$I$4229,"") -> 21 | I7: =COUNTIFS(Canon!$G$2:$G$4229,"*"&$A7&"*",Canon!$H$2:$H$4229,"<"&I$4,Canon!$I$2:$I$4229,">="&I$3)+COUNTIFS(Canon!$G$2:$G$4229,"*"&$A7&"*",Canon!$H$2:$H$4229,"<"&I$4,Canon!$I$2:$I$4229,"") -> 19 | J7: =COUNTIFS(Canon!$G$2:$G$4229,"*"&$A7&"*",Canon!$H$2:$H$4229,"<"&J$4,Canon!$I$2:$I$4229,">="&J$3)+COUNTIFS(Canon!$G$2:$G$4229,"*"&$A7&"*",Canon!$H$2:$H$4229,"<"&J$4,Canon!$I$2:$I$4229,"") -> 20 | ... M7: =COUNTIFS(Canon!$G$2:$G$4229,"*"&$A7&"*",Canon!$H$2:$H$4229,"<"&M$4,Canon!$I$2:$I$4229,">="&M$3)+COUNTIFS(Canon!$G$2:$G$4229,"*"&$A7&"*",Canon!$H$2:$H$4229,"<"&M$4,Canon!$I$2:$I$4229,"") -> 23
A8: AF-MAG | B8: Maghrib | C8: =COUNTIFS(Canon!$G$2:$G$4229,"*"&$A8&"*",Canon!$H$2:$H$4229,"<"&C$4,Canon!$I$2:$I$4229,">="&C$3)+COUNTIFS(Canon!$G$2:$G$4229,"*"&$A8&"*",Canon!$H$2:$H$4229,"<"&C$4,Canon!$I$2:$I$4229,"") -> 9 | D8: =COUNTIFS(Canon!$G$2:$G$4229,"*"&$A8&"*",Canon!$H$2:$H$4229,"<"&D$4,Canon!$I$2:$I$4229,">="&D$3)+COUNTIFS(Canon!$G$2:$G$4229,"*"&$A8&"*",Canon!$H$2:$H$4229,"<"&D$4,Canon!$I$2:$I$4229,"") -> 7 | E8: =COUNTIFS(Canon!$G$2:$G$4229,"*"&$A8&"*",Canon!$H$2:$H$4229,"<"&E$4,Canon!$I$2:$I$4229,">="&E$3)+COUNTIFS(Canon!$G$2:$G$4229,"*"&$A8&"*",Canon!$H$2:$H$4229,"<"&E$4,Canon!$I$2:$I$4229,"") -> 7 | F8: =COUNTIFS(Canon!$G$2:$G$4229,"*"&$A8&"*",Canon!$H$2:$H$4229,"<"&F$4,Canon!$I$2:$I$4229,">="&F$3)+COUNTIFS(Canon!$G$2:$G$4229,"*"&$A8&"*",Canon!$H$2:$H$4229,"<"&F$4,Canon!$I$2:$I$4229,"") -> 9 | G8: =COUNTIFS(Canon!$G$2:$G$4229,"*"&$A8&"*",Canon!$H$2:$H$4229,"<"&G$4,Canon!$I$2:$I$4229,">="&G$3)+COUNTIFS(Canon!$G$2:$G$4229,"*"&$A8&"*",Canon!$H$2:$H$4229,"<"&G$4,Canon!$I$2:$I$4229,"") -> 24 | H8: =COUNTIFS(Canon!$G$2:$G$4229,"*"&$A8&"*",Canon!$H$2:$H$4229,"<"&H$4,Canon!$I$2:$I$4229,">="&H$3)+COUNTIFS(Canon!$G$2:$G$4229,"*"&$A8&"*",Canon!$H$2:$H$4229,"<"&H$4,Canon!$I$2:$I$4229,"") -> 21 | I8: =COUNTIFS(Canon!$G$2:$G$4229,"*"&$A8&"*",Canon!$H$2:$H$4229,"<"&I$4,Canon!$I$2:$I$4229,">="&I$3)+COUNTIFS(Canon!$G$2:$G$4229,"*"&$A8&"*",Canon!$H$2:$H$4229,"<"&I$4,Canon!$I$2:$I$4229,"") -> 36 | J8: =COUNTIFS(Canon!$G$2:$G$4229,"*"&$A8&"*",Canon!$H$2:$H$4229,"<"&J$4,Canon!$I$2:$I$4229,">="&J$3)+COUNTIFS(Canon!$G$2:$G$4229,"*"&$A8&"*",Canon!$H$2:$H$4229,"<"&J$4,Canon!$I$2:$I$4229,"") -> 47 | ... M8: =COUNTIFS(Canon!$G$2:$G$4229,"*"&$A8&"*",Canon!$H$2:$H$4229,"<"&M$4,Canon!$I$2:$I$4229,">="&M$3)+COUNTIFS(Canon!$G$2:$G$4229,"*"&$A8&"*",Canon!$H$2:$H$4229,"<"&M$4,Canon!$I$2:$I$4229,"") -> 41
A9: AF-SAH | B9: Sahel and Western Sudan | C9: =COUNTIFS(Canon!$G$2:$G$4229,"*"&$A9&"*",Canon!$H$2:$H$4229,"<"&C$4,Canon!$I$2:$I$4229,">="&C$3)+COUNTIFS(Canon!$G$2:$G$4229,"*"&$A9&"*",Canon!$H$2:$H$4229,"<"&C$4,Canon!$I$2:$I$4229,"") -> 5 | D9: =COUNTIFS(Canon!$G$2:$G$4229,"*"&$A9&"*",Canon!$H$2:$H$4229,"<"&D$4,Canon!$I$2:$I$4229,">="&D$3)+COUNTIFS(Canon!$G$2:$G$4229,"*"&$A9&"*",Canon!$H$2:$H$4229,"<"&D$4,Canon!$I$2:$I$4229,"") -> 11 | E9: =COUNTIFS(Canon!$G$2:$G$4229,"*"&$A9&"*",Canon!$H$2:$H$4229,"<"&E$4,Canon!$I$2:$I$4229,">="&E$3)+COUNTIFS(Canon!$G$2:$G$4229,"*"&$A9&"*",Canon!$H$2:$H$4229,"<"&E$4,Canon!$I$2:$I$4229,"") -> 12 | F9: =COUNTIFS(Canon!$G$2:$G$4229,"*"&$A9&"*",Canon!$H$2:$H$4229,"<"&F$4,Canon!$I$2:$I$4229,">="&F$3)+COUNTIFS(Canon!$G$2:$G$4229,"*"&$A9&"*",Canon!$H$2:$H$4229,"<"&F$4,Canon!$I$2:$I$4229,"") -> 15 | G9: =COUNTIFS(Canon!$G$2:$G$4229,"*"&$A9&"*",Canon!$H$2:$H$4229,"<"&G$4,Canon!$I$2:$I$4229,">="&G$3)+COUNTIFS(Canon!$G$2:$G$4229,"*"&$A9&"*",Canon!$H$2:$H$4229,"<"&G$4,Canon!$I$2:$I$4229,"") -> 24 | H9: =COUNTIFS(Canon!$G$2:$G$4229,"*"&$A9&"*",Canon!$H$2:$H$4229,"<"&H$4,Canon!$I$2:$I$4229,">="&H$3)+COUNTIFS(Canon!$G$2:$G$4229,"*"&$A9&"*",Canon!$H$2:$H$4229,"<"&H$4,Canon!$I$2:$I$4229,"") -> 26 | I9: =COUNTIFS(Canon!$G$2:$G$4229,"*"&$A9&"*",Canon!$H$2:$H$4229,"<"&I$4,Canon!$I$2:$I$4229,">="&I$3)+COUNTIFS(Canon!$G$2:$G$4229,"*"&$A9&"*",Canon!$H$2:$H$4229,"<"&I$4,Canon!$I$2:$I$4229,"") -> 32 | J9: =COUNTIFS(Canon!$G$2:$G$4229,"*"&$A9&"*",Canon!$H$2:$H$4229,"<"&J$4,Canon!$I$2:$I$4229,">="&J$3)+COUNTIFS(Canon!$G$2:$G$4229,"*"&$A9&"*",Canon!$H$2:$H$4229,"<"&J$4,Canon!$I$2:$I$4229,"") -> 55 | ... M9: =COUNTIFS(Canon!$G$2:$G$4229,"*"&$A9&"*",Canon!$H$2:$H$4229,"<"&M$4,Canon!$I$2:$I$4229,">="&M$3)+COUNTIFS(Canon!$G$2:$G$4229,"*"&$A9&"*",Canon!$H$2:$H$4229,"<"&M$4,Canon!$I$2:$I$4229,"") -> 72
A10: AF-GUI | B10: Guinea Coast | C10: =COUNTIFS(Canon!$G$2:$G$4229,"*"&$A10&"*",Canon!$H$2:$H$4229,"<"&C$4,Canon!$I$2:$I$4229,">="&C$3)+COUNTIFS(Canon!$G$2:$G$4229,"*"&$A10&"*",Canon!$H$2:$H$4229,"<"&C$4,Canon!$I$2:$I$4229,"") -> 3 | D10: =COUNTIFS(Canon!$G$2:$G$4229,"*"&$A10&"*",Canon!$H$2:$H$4229,"<"&D$4,Canon!$I$2:$I$4229,">="&D$3)+COUNTIFS(Canon!$G$2:$G$4229,"*"&$A10&"*",Canon!$H$2:$H$4229,"<"&D$4,Canon!$I$2:$I$4229,"") -> 7 | E10: =COUNTIFS(Canon!$G$2:$G$4229,"*"&$A10&"*",Canon!$H$2:$H$4229,"<"&E$4,Canon!$I$2:$I$4229,">="&E$3)+COUNTIFS(Canon!$G$2:$G$4229,"*"&$A10&"*",Canon!$H$2:$H$4229,"<"&E$4,Canon!$I$2:$I$4229,"") -> 12 | F10: =COUNTIFS(Canon!$G$2:$G$4229,"*"&$A10&"*",Canon!$H$2:$H$4229,"<"&F$4,Canon!$I$2:$I$4229,">="&F$3)+COUNTIFS(Canon!$G$2:$G$4229,"*"&$A10&"*",Canon!$H$2:$H$4229,"<"&F$4,Canon!$I$2:$I$4229,"") -> 19 | G10: =COUNTIFS(Canon!$G$2:$G$4229,"*"&$A10&"*",Canon!$H$2:$H$4229,"<"&G$4,Canon!$I$2:$I$4229,">="&G$3)+COUNTIFS(Canon!$G$2:$G$4229,"*"&$A10&"*",Canon!$H$2:$H$4229,"<"&G$4,Canon!$I$2:$I$4229,"") -> 21 | H10: =COUNTIFS(Canon!$G$2:$G$4229,"*"&$A10&"*",Canon!$H$2:$H$4229,"<"&H$4,Canon!$I$2:$I$4229,">="&H$3)+COUNTIFS(Canon!$G$2:$G$4229,"*"&$A10&"*",Canon!$H$2:$H$4229,"<"&H$4,Canon!$I$2:$I$4229,"") -> 22 | I10: =COUNTIFS(Canon!$G$2:$G$4229,"*"&$A10&"*",Canon!$H$2:$H$4229,"<"&I$4,Canon!$I$2:$I$4229,">="&I$3)+COUNTIFS(Canon!$G$2:$G$4229,"*"&$A10&"*",Canon!$H$2:$H$4229,"<"&I$4,Canon!$I$2:$I$4229,"") -> 23 | J10: =COUNTIFS(Canon!$G$2:$G$4229,"*"&$A10&"*",Canon!$H$2:$H$4229,"<"&J$4,Canon!$I$2:$I$4229,">="&J$3)+COUNTIFS(Canon!$G$2:$G$4229,"*"&$A10&"*",Canon!$H$2:$H$4229,"<"&J$4,Canon!$I$2:$I$4229,"") -> 45 | ... M10: =COUNTIFS(Canon!$G$2:$G$4229,"*"&$A10&"*",Canon!$H$2:$H$4229,"<"&M$4,Canon!$I$2:$I$4229,">="&M$3)+COUNTIFS(Canon!$G$2:$G$4229,"*"&$A10&"*",Canon!$H$2:$H$4229,"<"&M$4,Canon!$I$2:$I$4229,"") -> 123
A11: AF-CEN | B11: Central Africa | C11: =COUNTIFS(Canon!$G$2:$G$4229,"*"&$A11&"*",Canon!$H$2:$H$4229,"<"&C$4,Canon!$I$2:$I$4229,">="&C$3)+COUNTIFS(Canon!$G$2:$G$4229,"*"&$A11&"*",Canon!$H$2:$H$4229,"<"&C$4,Canon!$I$2:$I$4229,"") -> 8 | D11: =COUNTIFS(Canon!$G$2:$G$4229,"*"&$A11&"*",Canon!$H$2:$H$4229,"<"&D$4,Canon!$I$2:$I$4229,">="&D$3)+COUNTIFS(Canon!$G$2:$G$4229,"*"&$A11&"*",Canon!$H$2:$H$4229,"<"&D$4,Canon!$I$2:$I$4229,"") -> 7 | E11: =COUNTIFS(Canon!$G$2:$G$4229,"*"&$A11&"*",Canon!$H$2:$H$4229,"<"&E$4,Canon!$I$2:$I$4229,">="&E$3)+COUNTIFS(Canon!$G$2:$G$4229,"*"&$A11&"*",Canon!$H$2:$H$4229,"<"&E$4,Canon!$I$2:$I$4229,"") -> 9 | F11: =COUNTIFS(Canon!$G$2:$G$4229,"*"&$A11&"*",Canon!$H$2:$H$4229,"<"&F$4,Canon!$I$2:$I$4229,">="&F$3)+COUNTIFS(Canon!$G$2:$G$4229,"*"&$A11&"*",Canon!$H$2:$H$4229,"<"&F$4,Canon!$I$2:$I$4229,"") -> 14 | G11: =COUNTIFS(Canon!$G$2:$G$4229,"*"&$A11&"*",Canon!$H$2:$H$4229,"<"&G$4,Canon!$I$2:$I$4229,">="&G$3)+COUNTIFS(Canon!$G$2:$G$4229,"*"&$A11&"*",Canon!$H$2:$H$4229,"<"&G$4,Canon!$I$2:$I$4229,"") -> 18 | H11: =COUNTIFS(Canon!$G$2:$G$4229,"*"&$A11&"*",Canon!$H$2:$H$4229,"<"&H$4,Canon!$I$2:$I$4229,">="&H$3)+COUNTIFS(Canon!$G$2:$G$4229,"*"&$A11&"*",Canon!$H$2:$H$4229,"<"&H$4,Canon!$I$2:$I$4229,"") -> 18 | I11: =COUNTIFS(Canon!$G$2:$G$4229,"*"&$A11&"*",Canon!$H$2:$H$4229,"<"&I$4,Canon!$I$2:$I$4229,">="&I$3)+COUNTIFS(Canon!$G$2:$G$4229,"*"&$A11&"*",Canon!$H$2:$H$4229,"<"&I$4,Canon!$I$2:$I$4229,"") -> 21 | J11: =COUNTIFS(Canon!$G$2:$G$4229,"*"&$A11&"*",Canon!$H$2:$H$4229,"<"&J$4,Canon!$I$2:$I$4229,">="&J$3)+COUNTIFS(Canon!$G$2:$G$4229,"*"&$A11&"*",Canon!$H$2:$H$4229,"<"&J$4,Canon!$I$2:$I$4229,"") -> 29 | ... M11: =COUNTIFS(Canon!$G$2:$G$4229,"*"&$A11&"*",Canon!$H$2:$H$4229,"<"&M$4,Canon!$I$2:$I$4229,">="&M$3)+COUNTIFS(Canon!$G$2:$G$4229,"*"&$A11&"*",Canon!$H$2:$H$4229,"<"&M$4,Canon!$I$2:$I$4229,"") -> 63
A12: AF-HRN | B12: Ethiopia and the Horn | C12: =COUNTIFS(Canon!$G$2:$G$4229,"*"&$A12&"*",Canon!$H$2:$H$4229,"<"&C$4,Canon!$I$2:$I$4229,">="&C$3)+COUNTIFS(Canon!$G$2:$G$4229,"*"&$A12&"*",Canon!$H$2:$H$4229,"<"&C$4,Canon!$I$2:$I$4229,"") -> 11 | D12: =COUNTIFS(Canon!$G$2:$G$4229,"*"&$A12&"*",Canon!$H$2:$H$4229,"<"&D$4,Canon!$I$2:$I$4229,">="&D$3)+COUNTIFS(Canon!$G$2:$G$4229,"*"&$A12&"*",Canon!$H$2:$H$4229,"<"&D$4,Canon!$I$2:$I$4229,"") -> 7 | E12: =COUNTIFS(Canon!$G$2:$G$4229,"*"&$A12&"*",Canon!$H$2:$H$4229,"<"&E$4,Canon!$I$2:$I$4229,">="&E$3)+COUNTIFS(Canon!$G$2:$G$4229,"*"&$A12&"*",Canon!$H$2:$H$4229,"<"&E$4,Canon!$I$2:$I$4229,"") -> 15 | F12: =COUNTIFS(Canon!$G$2:$G$4229,"*"&$A12&"*",Canon!$H$2:$H$4229,"<"&F$4,Canon!$I$2:$I$4229,">="&F$3)+COUNTIFS(Canon!$G$2:$G$4229,"*"&$A12&"*",Canon!$H$2:$H$4229,"<"&F$4,Canon!$I$2:$I$4229,"") -> 16 | G12: =COUNTIFS(Canon!$G$2:$G$4229,"*"&$A12&"*",Canon!$H$2:$H$4229,"<"&G$4,Canon!$I$2:$I$4229,">="&G$3)+COUNTIFS(Canon!$G$2:$G$4229,"*"&$A12&"*",Canon!$H$2:$H$4229,"<"&G$4,Canon!$I$2:$I$4229,"") -> 24 | H12: =COUNTIFS(Canon!$G$2:$G$4229,"*"&$A12&"*",Canon!$H$2:$H$4229,"<"&H$4,Canon!$I$2:$I$4229,">="&H$3)+COUNTIFS(Canon!$G$2:$G$4229,"*"&$A12&"*",Canon!$H$2:$H$4229,"<"&H$4,Canon!$I$2:$I$4229,"") -> 28 | I12: =COUNTIFS(Canon!$G$2:$G$4229,"*"&$A12&"*",Canon!$H$2:$H$4229,"<"&I$4,Canon!$I$2:$I$4229,">="&I$3)+COUNTIFS(Canon!$G$2:$G$4229,"*"&$A12&"*",Canon!$H$2:$H$4229,"<"&I$4,Canon!$I$2:$I$4229,"") -> 30 | J12: =COUNTIFS(Canon!$G$2:$G$4229,"*"&$A12&"*",Canon!$H$2:$H$4229,"<"&J$4,Canon!$I$2:$I$4229,">="&J$3)+COUNTIFS(Canon!$G$2:$G$4229,"*"&$A12&"*",Canon!$H$2:$H$4229,"<"&J$4,Canon!$I$2:$I$4229,"") -> 35 | ... M12: =COUNTIFS(Canon!$G$2:$G$4229,"*"&$A12&"*",Canon!$H$2:$H$4229,"<"&M$4,Canon!$I$2:$I$4229,">="&M$3)+COUNTIFS(Canon!$G$2:$G$4229,"*"&$A12&"*",Canon!$H$2:$H$4229,"<"&M$4,Canon!$I$2:$I$4229,"") -> 45
A13: AF-SWA | B13: Swahili coast and interior | C13: =COUNTIFS(Canon!$G$2:$G$4229,"*"&$A13&"*",Canon!$H$2:$H$4229,"<"&C$4,Canon!$I$2:$I$4229,">="&C$3)+COUNTIFS(Canon!$G$2:$G$4229,"*"&$A13&"*",Canon!$H$2:$H$4229,"<"&C$4,Canon!$I$2:$I$4229,"") -> 20 | D13: =COUNTIFS(Canon!$G$2:$G$4229,"*"&$A13&"*",Canon!$H$2:$H$4229,"<"&D$4,Canon!$I$2:$I$4229,">="&D$3)+COUNTIFS(Canon!$G$2:$G$4229,"*"&$A13&"*",Canon!$H$2:$H$4229,"<"&D$4,Canon!$I$2:$I$4229,"") -> 14 | E13: =COUNTIFS(Canon!$G$2:$G$4229,"*"&$A13&"*",Canon!$H$2:$H$4229,"<"&E$4,Canon!$I$2:$I$4229,">="&E$3)+COUNTIFS(Canon!$G$2:$G$4229,"*"&$A13&"*",Canon!$H$2:$H$4229,"<"&E$4,Canon!$I$2:$I$4229,"") -> 18 | F13: =COUNTIFS(Canon!$G$2:$G$4229,"*"&$A13&"*",Canon!$H$2:$H$4229,"<"&F$4,Canon!$I$2:$I$4229,">="&F$3)+COUNTIFS(Canon!$G$2:$G$4229,"*"&$A13&"*",Canon!$H$2:$H$4229,"<"&F$4,Canon!$I$2:$I$4229,"") -> 20 | G13: =COUNTIFS(Canon!$G$2:$G$4229,"*"&$A13&"*",Canon!$H$2:$H$4229,"<"&G$4,Canon!$I$2:$I$4229,">="&G$3)+COUNTIFS(Canon!$G$2:$G$4229,"*"&$A13&"*",Canon!$H$2:$H$4229,"<"&G$4,Canon!$I$2:$I$4229,"") -> 24 | H13: =COUNTIFS(Canon!$G$2:$G$4229,"*"&$A13&"*",Canon!$H$2:$H$4229,"<"&H$4,Canon!$I$2:$I$4229,">="&H$3)+COUNTIFS(Canon!$G$2:$G$4229,"*"&$A13&"*",Canon!$H$2:$H$4229,"<"&H$4,Canon!$I$2:$I$4229,"") -> 25 | I13: =COUNTIFS(Canon!$G$2:$G$4229,"*"&$A13&"*",Canon!$H$2:$H$4229,"<"&I$4,Canon!$I$2:$I$4229,">="&I$3)+COUNTIFS(Canon!$G$2:$G$4229,"*"&$A13&"*",Canon!$H$2:$H$4229,"<"&I$4,Canon!$I$2:$I$4229,"") -> 37 | J13: =COUNTIFS(Canon!$G$2:$G$4229,"*"&$A13&"*",Canon!$H$2:$H$4229,"<"&J$4,Canon!$I$2:$I$4229,">="&J$3)+COUNTIFS(Canon!$G$2:$G$4229,"*"&$A13&"*",Canon!$H$2:$H$4229,"<"&J$4,Canon!$I$2:$I$4229,"") -> 44 | ... M13: =COUNTIFS(Canon!$G$2:$G$4229,"*"&$A13&"*",Canon!$H$2:$H$4229,"<"&M$4,Canon!$I$2:$I$4229,">="&M$3)+COUNTIFS(Canon!$G$2:$G$4229,"*"&$A13&"*",Canon!$H$2:$H$4229,"<"&M$4,Canon!$I$2:$I$4229,"") -> 62
A14: AF-SOU | B14: Southern Africa | C14: =COUNTIFS(Canon!$G$2:$G$4229,"*"&$A14&"*",Canon!$H$2:$H$4229,"<"&C$4,Canon!$I$2:$I$4229,">="&C$3)+COUNTIFS(Canon!$G$2:$G$4229,"*"&$A14&"*",Canon!$H$2:$H$4229,"<"&C$4,Canon!$I$2:$I$4229,"") -> 29 | D14: =COUNTIFS(Canon!$G$2:$G$4229,"*"&$A14&"*",Canon!$H$2:$H$4229,"<"&D$4,Canon!$I$2:$I$4229,">="&D$3)+COUNTIFS(Canon!$G$2:$G$4229,"*"&$A14&"*",Canon!$H$2:$H$4229,"<"&D$4,Canon!$I$2:$I$4229,"") -> 20 | E14: =COUNTIFS(Canon!$G$2:$G$4229,"*"&$A14&"*",Canon!$H$2:$H$4229,"<"&E$4,Canon!$I$2:$I$4229,">="&E$3)+COUNTIFS(Canon!$G$2:$G$4229,"*"&$A14&"*",Canon!$H$2:$H$4229,"<"&E$4,Canon!$I$2:$I$4229,"") -> 23 | F14: =COUNTIFS(Canon!$G$2:$G$4229,"*"&$A14&"*",Canon!$H$2:$H$4229,"<"&F$4,Canon!$I$2:$I$4229,">="&F$3)+COUNTIFS(Canon!$G$2:$G$4229,"*"&$A14&"*",Canon!$H$2:$H$4229,"<"&F$4,Canon!$I$2:$I$4229,"") -> 25 | G14: =COUNTIFS(Canon!$G$2:$G$4229,"*"&$A14&"*",Canon!$H$2:$H$4229,"<"&G$4,Canon!$I$2:$I$4229,">="&G$3)+COUNTIFS(Canon!$G$2:$G$4229,"*"&$A14&"*",Canon!$H$2:$H$4229,"<"&G$4,Canon!$I$2:$I$4229,"") -> 28 | H14: =COUNTIFS(Canon!$G$2:$G$4229,"*"&$A14&"*",Canon!$H$2:$H$4229,"<"&H$4,Canon!$I$2:$I$4229,">="&H$3)+COUNTIFS(Canon!$G$2:$G$4229,"*"&$A14&"*",Canon!$H$2:$H$4229,"<"&H$4,Canon!$I$2:$I$4229,"") -> 28 | I14: =COUNTIFS(Canon!$G$2:$G$4229,"*"&$A14&"*",Canon!$H$2:$H$4229,"<"&I$4,Canon!$I$2:$I$4229,">="&I$3)+COUNTIFS(Canon!$G$2:$G$4229,"*"&$A14&"*",Canon!$H$2:$H$4229,"<"&I$4,Canon!$I$2:$I$4229,"") -> 30 | J14: =COUNTIFS(Canon!$G$2:$G$4229,"*"&$A14&"*",Canon!$H$2:$H$4229,"<"&J$4,Canon!$I$2:$I$4229,">="&J$3)+COUNTIFS(Canon!$G$2:$G$4229,"*"&$A14&"*",Canon!$H$2:$H$4229,"<"&J$4,Canon!$I$2:$I$4229,"") -> 42 | ... M14: =COUNTIFS(Canon!$G$2:$G$4229,"*"&$A14&"*",Canon!$H$2:$H$4229,"<"&M$4,Canon!$I$2:$I$4229,">="&M$3)+COUNTIFS(Canon!$G$2:$G$4229,"*"&$A14&"*",Canon!$H$2:$H$4229,"<"&M$4,Canon!$I$2:$I$4229,"") -> 51
A15: AF-MAD | B15: Madagascar and Indian Ocean islands | C15: =COUNTIFS(Canon!$G$2:$G$4229,"*"&$A15&"*",Canon!$H$2:$H$4229,"<"&C$4,Canon!$I$2:$I$4229,">="&C$3)+COUNTIFS(Canon!$G$2:$G$4229,"*"&$A15&"*",Canon!$H$2:$H$4229,"<"&C$4,Canon!$I$2:$I$4229,"") -> 0 | D15: =COUNTIFS(Canon!$G$2:$G$4229,"*"&$A15&"*",Canon!$H$2:$H$4229,"<"&D$4,Canon!$I$2:$I$4229,">="&D$3)+COUNTIFS(Canon!$G$2:$G$4229,"*"&$A15&"*",Canon!$H$2:$H$4229,"<"&D$4,Canon!$I$2:$I$4229,"") -> 0 | E15: =COUNTIFS(Canon!$G$2:$G$4229,"*"&$A15&"*",Canon!$H$2:$H$4229,"<"&E$4,Canon!$I$2:$I$4229,">="&E$3)+COUNTIFS(Canon!$G$2:$G$4229,"*"&$A15&"*",Canon!$H$2:$H$4229,"<"&E$4,Canon!$I$2:$I$4229,"") -> 4 | F15: =COUNTIFS(Canon!$G$2:$G$4229,"*"&$A15&"*",Canon!$H$2:$H$4229,"<"&F$4,Canon!$I$2:$I$4229,">="&F$3)+COUNTIFS(Canon!$G$2:$G$4229,"*"&$A15&"*",Canon!$H$2:$H$4229,"<"&F$4,Canon!$I$2:$I$4229,"") -> 6 | G15: =COUNTIFS(Canon!$G$2:$G$4229,"*"&$A15&"*",Canon!$H$2:$H$4229,"<"&G$4,Canon!$I$2:$I$4229,">="&G$3)+COUNTIFS(Canon!$G$2:$G$4229,"*"&$A15&"*",Canon!$H$2:$H$4229,"<"&G$4,Canon!$I$2:$I$4229,"") -> 6 | H15: =COUNTIFS(Canon!$G$2:$G$4229,"*"&$A15&"*",Canon!$H$2:$H$4229,"<"&H$4,Canon!$I$2:$I$4229,">="&H$3)+COUNTIFS(Canon!$G$2:$G$4229,"*"&$A15&"*",Canon!$H$2:$H$4229,"<"&H$4,Canon!$I$2:$I$4229,"") -> 6 | I15: =COUNTIFS(Canon!$G$2:$G$4229,"*"&$A15&"*",Canon!$H$2:$H$4229,"<"&I$4,Canon!$I$2:$I$4229,">="&I$3)+COUNTIFS(Canon!$G$2:$G$4229,"*"&$A15&"*",Canon!$H$2:$H$4229,"<"&I$4,Canon!$I$2:$I$4229,"") -> 12 | J15: =COUNTIFS(Canon!$G$2:$G$4229,"*"&$A15&"*",Canon!$H$2:$H$4229,"<"&J$4,Canon!$I$2:$I$4229,">="&J$3)+COUNTIFS(Canon!$G$2:$G$4229,"*"&$A15&"*",Canon!$H$2:$H$4229,"<"&J$4,Canon!$I$2:$I$4229,"") -> 15 | ... M15: =COUNTIFS(Canon!$G$2:$G$4229,"*"&$A15&"*",Canon!$H$2:$H$4229,"<"&M$4,Canon!$I$2:$I$4229,">="&M$3)+COUNTIFS(Canon!$G$2:$G$4229,"*"&$A15&"*",Canon!$H$2:$H$4229,"<"&M$4,Canon!$I$2:$I$4229,"") -> 22 | N15: B01–B02: human arrival in Madagascar is debated (claims before 8000 BCE contested); likely no makers to record
A16: AM-ARC | B16: Arctic | C16: =COUNTIFS(Canon!$G$2:$G$4229,"*"&$A16&"*",Canon!$H$2:$H$4229,"<"&C$4,Canon!$I$2:$I$4229,">="&C$3)+COUNTIFS(Canon!$G$2:$G$4229,"*"&$A16&"*",Canon!$H$2:$H$4229,"<"&C$4,Canon!$I$2:$I$4229,"") -> 3 | D16: =COUNTIFS(Canon!$G$2:$G$4229,"*"&$A16&"*",Canon!$H$2:$H$4229,"<"&D$4,Canon!$I$2:$I$4229,">="&D$3)+COUNTIFS(Canon!$G$2:$G$4229,"*"&$A16&"*",Canon!$H$2:$H$4229,"<"&D$4,Canon!$I$2:$I$4229,"") -> 5 | E16: =COUNTIFS(Canon!$G$2:$G$4229,"*"&$A16&"*",Canon!$H$2:$H$4229,"<"&E$4,Canon!$I$2:$I$4229,">="&E$3)+COUNTIFS(Canon!$G$2:$G$4229,"*"&$A16&"*",Canon!$H$2:$H$4229,"<"&E$4,Canon!$I$2:$I$4229,"") -> 9 | F16: =COUNTIFS(Canon!$G$2:$G$4229,"*"&$A16&"*",Canon!$H$2:$H$4229,"<"&F$4,Canon!$I$2:$I$4229,">="&F$3)+COUNTIFS(Canon!$G$2:$G$4229,"*"&$A16&"*",Canon!$H$2:$H$4229,"<"&F$4,Canon!$I$2:$I$4229,"") -> 9 | G16: =COUNTIFS(Canon!$G$2:$G$4229,"*"&$A16&"*",Canon!$H$2:$H$4229,"<"&G$4,Canon!$I$2:$I$4229,">="&G$3)+COUNTIFS(Canon!$G$2:$G$4229,"*"&$A16&"*",Canon!$H$2:$H$4229,"<"&G$4,Canon!$I$2:$I$4229,"") -> 11 | H16: =COUNTIFS(Canon!$G$2:$G$4229,"*"&$A16&"*",Canon!$H$2:$H$4229,"<"&H$4,Canon!$I$2:$I$4229,">="&H$3)+COUNTIFS(Canon!$G$2:$G$4229,"*"&$A16&"*",Canon!$H$2:$H$4229,"<"&H$4,Canon!$I$2:$I$4229,"") -> 10 | I16: =COUNTIFS(Canon!$G$2:$G$4229,"*"&$A16&"*",Canon!$H$2:$H$4229,"<"&I$4,Canon!$I$2:$I$4229,">="&I$3)+COUNTIFS(Canon!$G$2:$G$4229,"*"&$A16&"*",Canon!$H$2:$H$4229,"<"&I$4,Canon!$I$2:$I$4229,"") -> 12 | J16: =COUNTIFS(Canon!$G$2:$G$4229,"*"&$A16&"*",Canon!$H$2:$H$4229,"<"&J$4,Canon!$I$2:$I$4229,">="&J$3)+COUNTIFS(Canon!$G$2:$G$4229,"*"&$A16&"*",Canon!$H$2:$H$4229,"<"&J$4,Canon!$I$2:$I$4229,"") -> 21 | ... M16: =COUNTIFS(Canon!$G$2:$G$4229,"*"&$A16&"*",Canon!$H$2:$H$4229,"<"&M$4,Canon!$I$2:$I$4229,">="&M$3)+COUNTIFS(Canon!$G$2:$G$4229,"*"&$A16&"*",Canon!$H$2:$H$4229,"<"&M$4,Canon!$I$2:$I$4229,"") -> 28
A17: AM-NWC | B17: Northwest Coast | C17: =COUNTIFS(Canon!$G$2:$G$4229,"*"&$A17&"*",Canon!$H$2:$H$4229,"<"&C$4,Canon!$I$2:$I$4229,">="&C$3)+COUNTIFS(Canon!$G$2:$G$4229,"*"&$A17&"*",Canon!$H$2:$H$4229,"<"&C$4,Canon!$I$2:$I$4229,"") -> 3 | D17: =COUNTIFS(Canon!$G$2:$G$4229,"*"&$A17&"*",Canon!$H$2:$H$4229,"<"&D$4,Canon!$I$2:$I$4229,">="&D$3)+COUNTIFS(Canon!$G$2:$G$4229,"*"&$A17&"*",Canon!$H$2:$H$4229,"<"&D$4,Canon!$I$2:$I$4229,"") -> 3 | E17: =COUNTIFS(Canon!$G$2:$G$4229,"*"&$A17&"*",Canon!$H$2:$H$4229,"<"&E$4,Canon!$I$2:$I$4229,">="&E$3)+COUNTIFS(Canon!$G$2:$G$4229,"*"&$A17&"*",Canon!$H$2:$H$4229,"<"&E$4,Canon!$I$2:$I$4229,"") -> 3 | F17: =COUNTIFS(Canon!$G$2:$G$4229,"*"&$A17&"*",Canon!$H$2:$H$4229,"<"&F$4,Canon!$I$2:$I$4229,">="&F$3)+COUNTIFS(Canon!$G$2:$G$4229,"*"&$A17&"*",Canon!$H$2:$H$4229,"<"&F$4,Canon!$I$2:$I$4229,"") -> 4 | G17: =COUNTIFS(Canon!$G$2:$G$4229,"*"&$A17&"*",Canon!$H$2:$H$4229,"<"&G$4,Canon!$I$2:$I$4229,">="&G$3)+COUNTIFS(Canon!$G$2:$G$4229,"*"&$A17&"*",Canon!$H$2:$H$4229,"<"&G$4,Canon!$I$2:$I$4229,"") -> 6 | H17: =COUNTIFS(Canon!$G$2:$G$4229,"*"&$A17&"*",Canon!$H$2:$H$4229,"<"&H$4,Canon!$I$2:$I$4229,">="&H$3)+COUNTIFS(Canon!$G$2:$G$4229,"*"&$A17&"*",Canon!$H$2:$H$4229,"<"&H$4,Canon!$I$2:$I$4229,"") -> 5 | I17: =COUNTIFS(Canon!$G$2:$G$4229,"*"&$A17&"*",Canon!$H$2:$H$4229,"<"&I$4,Canon!$I$2:$I$4229,">="&I$3)+COUNTIFS(Canon!$G$2:$G$4229,"*"&$A17&"*",Canon!$H$2:$H$4229,"<"&I$4,Canon!$I$2:$I$4229,"") -> 5 | J17: =COUNTIFS(Canon!$G$2:$G$4229,"*"&$A17&"*",Canon!$H$2:$H$4229,"<"&J$4,Canon!$I$2:$I$4229,">="&J$3)+COUNTIFS(Canon!$G$2:$G$4229,"*"&$A17&"*",Canon!$H$2:$H$4229,"<"&J$4,Canon!$I$2:$I$4229,"") -> 10 | ... M17: =COUNTIFS(Canon!$G$2:$G$4229,"*"&$A17&"*",Canon!$H$2:$H$4229,"<"&M$4,Canon!$I$2:$I$4229,">="&M$3)+COUNTIFS(Canon!$G$2:$G$4229,"*"&$A17&"*",Canon!$H$2:$H$4229,"<"&M$4,Canon!$I$2:$I$4229,"") -> 29
A18: AM-WST | B18: North American West | C18: =COUNTIFS(Canon!$G$2:$G$4229,"*"&$A18&"*",Canon!$H$2:$H$4229,"<"&C$4,Canon!$I$2:$I$4229,">="&C$3)+COUNTIFS(Canon!$G$2:$G$4229,"*"&$A18&"*",Canon!$H$2:$H$4229,"<"&C$4,Canon!$I$2:$I$4229,"") -> 8 | D18: =COUNTIFS(Canon!$G$2:$G$4229,"*"&$A18&"*",Canon!$H$2:$H$4229,"<"&D$4,Canon!$I$2:$I$4229,">="&D$3)+COUNTIFS(Canon!$G$2:$G$4229,"*"&$A18&"*",Canon!$H$2:$H$4229,"<"&D$4,Canon!$I$2:$I$4229,"") -> 8 | E18: =COUNTIFS(Canon!$G$2:$G$4229,"*"&$A18&"*",Canon!$H$2:$H$4229,"<"&E$4,Canon!$I$2:$I$4229,">="&E$3)+COUNTIFS(Canon!$G$2:$G$4229,"*"&$A18&"*",Canon!$H$2:$H$4229,"<"&E$4,Canon!$I$2:$I$4229,"") -> 10 | F18: =COUNTIFS(Canon!$G$2:$G$4229,"*"&$A18&"*",Canon!$H$2:$H$4229,"<"&F$4,Canon!$I$2:$I$4229,">="&F$3)+COUNTIFS(Canon!$G$2:$G$4229,"*"&$A18&"*",Canon!$H$2:$H$4229,"<"&F$4,Canon!$I$2:$I$4229,"") -> 13 | G18: =COUNTIFS(Canon!$G$2:$G$4229,"*"&$A18&"*",Canon!$H$2:$H$4229,"<"&G$4,Canon!$I$2:$I$4229,">="&G$3)+COUNTIFS(Canon!$G$2:$G$4229,"*"&$A18&"*",Canon!$H$2:$H$4229,"<"&G$4,Canon!$I$2:$I$4229,"") -> 13 | H18: =COUNTIFS(Canon!$G$2:$G$4229,"*"&$A18&"*",Canon!$H$2:$H$4229,"<"&H$4,Canon!$I$2:$I$4229,">="&H$3)+COUNTIFS(Canon!$G$2:$G$4229,"*"&$A18&"*",Canon!$H$2:$H$4229,"<"&H$4,Canon!$I$2:$I$4229,"") -> 15 | I18: =COUNTIFS(Canon!$G$2:$G$4229,"*"&$A18&"*",Canon!$H$2:$H$4229,"<"&I$4,Canon!$I$2:$I$4229,">="&I$3)+COUNTIFS(Canon!$G$2:$G$4229,"*"&$A18&"*",Canon!$H$2:$H$4229,"<"&I$4,Canon!$I$2:$I$4229,"") -> 26 | J18: =COUNTIFS(Canon!$G$2:$G$4229,"*"&$A18&"*",Canon!$H$2:$H$4229,"<"&J$4,Canon!$I$2:$I$4229,">="&J$3)+COUNTIFS(Canon!$G$2:$G$4229,"*"&$A18&"*",Canon!$H$2:$H$4229,"<"&J$4,Canon!$I$2:$I$4229,"") -> 37 | ... M18: =COUNTIFS(Canon!$G$2:$G$4229,"*"&$A18&"*",Canon!$H$2:$H$4229,"<"&M$4,Canon!$I$2:$I$4229,">="&M$3)+COUNTIFS(Canon!$G$2:$G$4229,"*"&$A18&"*",Canon!$H$2:$H$4229,"<"&M$4,Canon!$I$2:$I$4229,"") -> 91
A19: AM-EWD | B19: Eastern Woodlands | C19: =COUNTIFS(Canon!$G$2:$G$4229,"*"&$A19&"*",Canon!$H$2:$H$4229,"<"&C$4,Canon!$I$2:$I$4229,">="&C$3)+COUNTIFS(Canon!$G$2:$G$4229,"*"&$A19&"*",Canon!$H$2:$H$4229,"<"&C$4,Canon!$I$2:$I$4229,"") -> 2 | D19: =COUNTIFS(Canon!$G$2:$G$4229,"*"&$A19&"*",Canon!$H$2:$H$4229,"<"&D$4,Canon!$I$2:$I$4229,">="&D$3)+COUNTIFS(Canon!$G$2:$G$4229,"*"&$A19&"*",Canon!$H$2:$H$4229,"<"&D$4,Canon!$I$2:$I$4229,"") -> 10 | E19: =COUNTIFS(Canon!$G$2:$G$4229,"*"&$A19&"*",Canon!$H$2:$H$4229,"<"&E$4,Canon!$I$2:$I$4229,">="&E$3)+COUNTIFS(Canon!$G$2:$G$4229,"*"&$A19&"*",Canon!$H$2:$H$4229,"<"&E$4,Canon!$I$2:$I$4229,"") -> 16 | F19: =COUNTIFS(Canon!$G$2:$G$4229,"*"&$A19&"*",Canon!$H$2:$H$4229,"<"&F$4,Canon!$I$2:$I$4229,">="&F$3)+COUNTIFS(Canon!$G$2:$G$4229,"*"&$A19&"*",Canon!$H$2:$H$4229,"<"&F$4,Canon!$I$2:$I$4229,"") -> 18 | G19: =COUNTIFS(Canon!$G$2:$G$4229,"*"&$A19&"*",Canon!$H$2:$H$4229,"<"&G$4,Canon!$I$2:$I$4229,">="&G$3)+COUNTIFS(Canon!$G$2:$G$4229,"*"&$A19&"*",Canon!$H$2:$H$4229,"<"&G$4,Canon!$I$2:$I$4229,"") -> 24 | H19: =COUNTIFS(Canon!$G$2:$G$4229,"*"&$A19&"*",Canon!$H$2:$H$4229,"<"&H$4,Canon!$I$2:$I$4229,">="&H$3)+COUNTIFS(Canon!$G$2:$G$4229,"*"&$A19&"*",Canon!$H$2:$H$4229,"<"&H$4,Canon!$I$2:$I$4229,"") -> 21 | I19: =COUNTIFS(Canon!$G$2:$G$4229,"*"&$A19&"*",Canon!$H$2:$H$4229,"<"&I$4,Canon!$I$2:$I$4229,">="&I$3)+COUNTIFS(Canon!$G$2:$G$4229,"*"&$A19&"*",Canon!$H$2:$H$4229,"<"&I$4,Canon!$I$2:$I$4229,"") -> 25 | J19: =COUNTIFS(Canon!$G$2:$G$4229,"*"&$A19&"*",Canon!$H$2:$H$4229,"<"&J$4,Canon!$I$2:$I$4229,">="&J$3)+COUNTIFS(Canon!$G$2:$G$4229,"*"&$A19&"*",Canon!$H$2:$H$4229,"<"&J$4,Canon!$I$2:$I$4229,"") -> 26 | ... M19: =COUNTIFS(Canon!$G$2:$G$4229,"*"&$A19&"*",Canon!$H$2:$H$4229,"<"&M$4,Canon!$I$2:$I$4229,">="&M$3)+COUNTIFS(Canon!$G$2:$G$4229,"*"&$A19&"*",Canon!$H$2:$H$4229,"<"&M$4,Canon!$I$2:$I$4229,"") -> 162
A20: AM-MES | B20: Mesoamerica | C20: =COUNTIFS(Canon!$G$2:$G$4229,"*"&$A20&"*",Canon!$H$2:$H$4229,"<"&C$4,Canon!$I$2:$I$4229,">="&C$3)+COUNTIFS(Canon!$G$2:$G$4229,"*"&$A20&"*",Canon!$H$2:$H$4229,"<"&C$4,Canon!$I$2:$I$4229,"") -> 5 | D20: =COUNTIFS(Canon!$G$2:$G$4229,"*"&$A20&"*",Canon!$H$2:$H$4229,"<"&D$4,Canon!$I$2:$I$4229,">="&D$3)+COUNTIFS(Canon!$G$2:$G$4229,"*"&$A20&"*",Canon!$H$2:$H$4229,"<"&D$4,Canon!$I$2:$I$4229,"") -> 13 | E20: =COUNTIFS(Canon!$G$2:$G$4229,"*"&$A20&"*",Canon!$H$2:$H$4229,"<"&E$4,Canon!$I$2:$I$4229,">="&E$3)+COUNTIFS(Canon!$G$2:$G$4229,"*"&$A20&"*",Canon!$H$2:$H$4229,"<"&E$4,Canon!$I$2:$I$4229,"") -> 14 | F20: =COUNTIFS(Canon!$G$2:$G$4229,"*"&$A20&"*",Canon!$H$2:$H$4229,"<"&F$4,Canon!$I$2:$I$4229,">="&F$3)+COUNTIFS(Canon!$G$2:$G$4229,"*"&$A20&"*",Canon!$H$2:$H$4229,"<"&F$4,Canon!$I$2:$I$4229,"") -> 31 | G20: =COUNTIFS(Canon!$G$2:$G$4229,"*"&$A20&"*",Canon!$H$2:$H$4229,"<"&G$4,Canon!$I$2:$I$4229,">="&G$3)+COUNTIFS(Canon!$G$2:$G$4229,"*"&$A20&"*",Canon!$H$2:$H$4229,"<"&G$4,Canon!$I$2:$I$4229,"") -> 50 | H20: =COUNTIFS(Canon!$G$2:$G$4229,"*"&$A20&"*",Canon!$H$2:$H$4229,"<"&H$4,Canon!$I$2:$I$4229,">="&H$3)+COUNTIFS(Canon!$G$2:$G$4229,"*"&$A20&"*",Canon!$H$2:$H$4229,"<"&H$4,Canon!$I$2:$I$4229,"") -> 47 | I20: =COUNTIFS(Canon!$G$2:$G$4229,"*"&$A20&"*",Canon!$H$2:$H$4229,"<"&I$4,Canon!$I$2:$I$4229,">="&I$3)+COUNTIFS(Canon!$G$2:$G$4229,"*"&$A20&"*",Canon!$H$2:$H$4229,"<"&I$4,Canon!$I$2:$I$4229,"") -> 65 | J20: =COUNTIFS(Canon!$G$2:$G$4229,"*"&$A20&"*",Canon!$H$2:$H$4229,"<"&J$4,Canon!$I$2:$I$4229,">="&J$3)+COUNTIFS(Canon!$G$2:$G$4229,"*"&$A20&"*",Canon!$H$2:$H$4229,"<"&J$4,Canon!$I$2:$I$4229,"") -> 66 | ... M20: =COUNTIFS(Canon!$G$2:$G$4229,"*"&$A20&"*",Canon!$H$2:$H$4229,"<"&M$4,Canon!$I$2:$I$4229,">="&M$3)+COUNTIFS(Canon!$G$2:$G$4229,"*"&$A20&"*",Canon!$H$2:$H$4229,"<"&M$4,Canon!$I$2:$I$4229,"") -> 41
A21: AM-CAM | B21: Central America | C21: =COUNTIFS(Canon!$G$2:$G$4229,"*"&$A21&"*",Canon!$H$2:$H$4229,"<"&C$4,Canon!$I$2:$I$4229,">="&C$3)+COUNTIFS(Canon!$G$2:$G$4229,"*"&$A21&"*",Canon!$H$2:$H$4229,"<"&C$4,Canon!$I$2:$I$4229,"") -> 1 | D21: =COUNTIFS(Canon!$G$2:$G$4229,"*"&$A21&"*",Canon!$H$2:$H$4229,"<"&D$4,Canon!$I$2:$I$4229,">="&D$3)+COUNTIFS(Canon!$G$2:$G$4229,"*"&$A21&"*",Canon!$H$2:$H$4229,"<"&D$4,Canon!$I$2:$I$4229,"") -> 3 | E21: =COUNTIFS(Canon!$G$2:$G$4229,"*"&$A21&"*",Canon!$H$2:$H$4229,"<"&E$4,Canon!$I$2:$I$4229,">="&E$3)+COUNTIFS(Canon!$G$2:$G$4229,"*"&$A21&"*",Canon!$H$2:$H$4229,"<"&E$4,Canon!$I$2:$I$4229,"") -> 4 | F21: =COUNTIFS(Canon!$G$2:$G$4229,"*"&$A21&"*",Canon!$H$2:$H$4229,"<"&F$4,Canon!$I$2:$I$4229,">="&F$3)+COUNTIFS(Canon!$G$2:$G$4229,"*"&$A21&"*",Canon!$H$2:$H$4229,"<"&F$4,Canon!$I$2:$I$4229,"") -> 6 | G21: =COUNTIFS(Canon!$G$2:$G$4229,"*"&$A21&"*",Canon!$H$2:$H$4229,"<"&G$4,Canon!$I$2:$I$4229,">="&G$3)+COUNTIFS(Canon!$G$2:$G$4229,"*"&$A21&"*",Canon!$H$2:$H$4229,"<"&G$4,Canon!$I$2:$I$4229,"") -> 9 | H21: =COUNTIFS(Canon!$G$2:$G$4229,"*"&$A21&"*",Canon!$H$2:$H$4229,"<"&H$4,Canon!$I$2:$I$4229,">="&H$3)+COUNTIFS(Canon!$G$2:$G$4229,"*"&$A21&"*",Canon!$H$2:$H$4229,"<"&H$4,Canon!$I$2:$I$4229,"") -> 17 | I21: =COUNTIFS(Canon!$G$2:$G$4229,"*"&$A21&"*",Canon!$H$2:$H$4229,"<"&I$4,Canon!$I$2:$I$4229,">="&I$3)+COUNTIFS(Canon!$G$2:$G$4229,"*"&$A21&"*",Canon!$H$2:$H$4229,"<"&I$4,Canon!$I$2:$I$4229,"") -> 23 | J21: =COUNTIFS(Canon!$G$2:$G$4229,"*"&$A21&"*",Canon!$H$2:$H$4229,"<"&J$4,Canon!$I$2:$I$4229,">="&J$3)+COUNTIFS(Canon!$G$2:$G$4229,"*"&$A21&"*",Canon!$H$2:$H$4229,"<"&J$4,Canon!$I$2:$I$4229,"") -> 16 | ... M21: =COUNTIFS(Canon!$G$2:$G$4229,"*"&$A21&"*",Canon!$H$2:$H$4229,"<"&M$4,Canon!$I$2:$I$4229,">="&M$3)+COUNTIFS(Canon!$G$2:$G$4229,"*"&$A21&"*",Canon!$H$2:$H$4229,"<"&M$4,Canon!$I$2:$I$4229,"") -> 15
A22: AM-CAR | B22: Caribbean | C22: =COUNTIFS(Canon!$G$2:$G$4229,"*"&$A22&"*",Canon!$H$2:$H$4229,"<"&C$4,Canon!$I$2:$I$4229,">="&C$3)+COUNTIFS(Canon!$G$2:$G$4229,"*"&$A22&"*",Canon!$H$2:$H$4229,"<"&C$4,Canon!$I$2:$I$4229,"") -> 2 | D22: =COUNTIFS(Canon!$G$2:$G$4229,"*"&$A22&"*",Canon!$H$2:$H$4229,"<"&D$4,Canon!$I$2:$I$4229,">="&D$3)+COUNTIFS(Canon!$G$2:$G$4229,"*"&$A22&"*",Canon!$H$2:$H$4229,"<"&D$4,Canon!$I$2:$I$4229,"") -> 2 | E22: =COUNTIFS(Canon!$G$2:$G$4229,"*"&$A22&"*",Canon!$H$2:$H$4229,"<"&E$4,Canon!$I$2:$I$4229,">="&E$3)+COUNTIFS(Canon!$G$2:$G$4229,"*"&$A22&"*",Canon!$H$2:$H$4229,"<"&E$4,Canon!$I$2:$I$4229,"") -> 5 | F22: =COUNTIFS(Canon!$G$2:$G$4229,"*"&$A22&"*",Canon!$H$2:$H$4229,"<"&F$4,Canon!$I$2:$I$4229,">="&F$3)+COUNTIFS(Canon!$G$2:$G$4229,"*"&$A22&"*",Canon!$H$2:$H$4229,"<"&F$4,Canon!$I$2:$I$4229,"") -> 5 | G22: =COUNTIFS(Canon!$G$2:$G$4229,"*"&$A22&"*",Canon!$H$2:$H$4229,"<"&G$4,Canon!$I$2:$I$4229,">="&G$3)+COUNTIFS(Canon!$G$2:$G$4229,"*"&$A22&"*",Canon!$H$2:$H$4229,"<"&G$4,Canon!$I$2:$I$4229,"") -> 8 | H22: =COUNTIFS(Canon!$G$2:$G$4229,"*"&$A22&"*",Canon!$H$2:$H$4229,"<"&H$4,Canon!$I$2:$I$4229,">="&H$3)+COUNTIFS(Canon!$G$2:$G$4229,"*"&$A22&"*",Canon!$H$2:$H$4229,"<"&H$4,Canon!$I$2:$I$4229,"") -> 6 | I22: =COUNTIFS(Canon!$G$2:$G$4229,"*"&$A22&"*",Canon!$H$2:$H$4229,"<"&I$4,Canon!$I$2:$I$4229,">="&I$3)+COUNTIFS(Canon!$G$2:$G$4229,"*"&$A22&"*",Canon!$H$2:$H$4229,"<"&I$4,Canon!$I$2:$I$4229,"") -> 10 | J22: =COUNTIFS(Canon!$G$2:$G$4229,"*"&$A22&"*",Canon!$H$2:$H$4229,"<"&J$4,Canon!$I$2:$I$4229,">="&J$3)+COUNTIFS(Canon!$G$2:$G$4229,"*"&$A22&"*",Canon!$H$2:$H$4229,"<"&J$4,Canon!$I$2:$I$4229,"") -> 13 | ... M22: =COUNTIFS(Canon!$G$2:$G$4229,"*"&$A22&"*",Canon!$H$2:$H$4229,"<"&M$4,Canon!$I$2:$I$4229,">="&M$3)+COUNTIFS(Canon!$G$2:$G$4229,"*"&$A22&"*",Canon!$H$2:$H$4229,"<"&M$4,Canon!$I$2:$I$4229,"") -> 40
A23: AM-AND | B23: Andes and Pacific coast | C23: =COUNTIFS(Canon!$G$2:$G$4229,"*"&$A23&"*",Canon!$H$2:$H$4229,"<"&C$4,Canon!$I$2:$I$4229,">="&C$3)+COUNTIFS(Canon!$G$2:$G$4229,"*"&$A23&"*",Canon!$H$2:$H$4229,"<"&C$4,Canon!$I$2:$I$4229,"") -> 6 | D23: =COUNTIFS(Canon!$G$2:$G$4229,"*"&$A23&"*",Canon!$H$2:$H$4229,"<"&D$4,Canon!$I$2:$I$4229,">="&D$3)+COUNTIFS(Canon!$G$2:$G$4229,"*"&$A23&"*",Canon!$H$2:$H$4229,"<"&D$4,Canon!$I$2:$I$4229,"") -> 20 | E23: =COUNTIFS(Canon!$G$2:$G$4229,"*"&$A23&"*",Canon!$H$2:$H$4229,"<"&E$4,Canon!$I$2:$I$4229,">="&E$3)+COUNTIFS(Canon!$G$2:$G$4229,"*"&$A23&"*",Canon!$H$2:$H$4229,"<"&E$4,Canon!$I$2:$I$4229,"") -> 42 | F23: =COUNTIFS(Canon!$G$2:$G$4229,"*"&$A23&"*",Canon!$H$2:$H$4229,"<"&F$4,Canon!$I$2:$I$4229,">="&F$3)+COUNTIFS(Canon!$G$2:$G$4229,"*"&$A23&"*",Canon!$H$2:$H$4229,"<"&F$4,Canon!$I$2:$I$4229,"") -> 49 | G23: =COUNTIFS(Canon!$G$2:$G$4229,"*"&$A23&"*",Canon!$H$2:$H$4229,"<"&G$4,Canon!$I$2:$I$4229,">="&G$3)+COUNTIFS(Canon!$G$2:$G$4229,"*"&$A23&"*",Canon!$H$2:$H$4229,"<"&G$4,Canon!$I$2:$I$4229,"") -> 60 | H23: =COUNTIFS(Canon!$G$2:$G$4229,"*"&$A23&"*",Canon!$H$2:$H$4229,"<"&H$4,Canon!$I$2:$I$4229,">="&H$3)+COUNTIFS(Canon!$G$2:$G$4229,"*"&$A23&"*",Canon!$H$2:$H$4229,"<"&H$4,Canon!$I$2:$I$4229,"") -> 61 | I23: =COUNTIFS(Canon!$G$2:$G$4229,"*"&$A23&"*",Canon!$H$2:$H$4229,"<"&I$4,Canon!$I$2:$I$4229,">="&I$3)+COUNTIFS(Canon!$G$2:$G$4229,"*"&$A23&"*",Canon!$H$2:$H$4229,"<"&I$4,Canon!$I$2:$I$4229,"") -> 83 | J23: =COUNTIFS(Canon!$G$2:$G$4229,"*"&$A23&"*",Canon!$H$2:$H$4229,"<"&J$4,Canon!$I$2:$I$4229,">="&J$3)+COUNTIFS(Canon!$G$2:$G$4229,"*"&$A23&"*",Canon!$H$2:$H$4229,"<"&J$4,Canon!$I$2:$I$4229,"") -> 74 | ... M23: =COUNTIFS(Canon!$G$2:$G$4229,"*"&$A23&"*",Canon!$H$2:$H$4229,"<"&M$4,Canon!$I$2:$I$4229,">="&M$3)+COUNTIFS(Canon!$G$2:$G$4229,"*"&$A23&"*",Canon!$H$2:$H$4229,"<"&M$4,Canon!$I$2:$I$4229,"") -> 71
A24: AM-AMZ | B24: Amazonia and lowlands | C24: =COUNTIFS(Canon!$G$2:$G$4229,"*"&$A24&"*",Canon!$H$2:$H$4229,"<"&C$4,Canon!$I$2:$I$4229,">="&C$3)+COUNTIFS(Canon!$G$2:$G$4229,"*"&$A24&"*",Canon!$H$2:$H$4229,"<"&C$4,Canon!$I$2:$I$4229,"") -> 3 | D24: =COUNTIFS(Canon!$G$2:$G$4229,"*"&$A24&"*",Canon!$H$2:$H$4229,"<"&D$4,Canon!$I$2:$I$4229,">="&D$3)+COUNTIFS(Canon!$G$2:$G$4229,"*"&$A24&"*",Canon!$H$2:$H$4229,"<"&D$4,Canon!$I$2:$I$4229,"") -> 10 | E24: =COUNTIFS(Canon!$G$2:$G$4229,"*"&$A24&"*",Canon!$H$2:$H$4229,"<"&E$4,Canon!$I$2:$I$4229,">="&E$3)+COUNTIFS(Canon!$G$2:$G$4229,"*"&$A24&"*",Canon!$H$2:$H$4229,"<"&E$4,Canon!$I$2:$I$4229,"") -> 10 | F24: =COUNTIFS(Canon!$G$2:$G$4229,"*"&$A24&"*",Canon!$H$2:$H$4229,"<"&F$4,Canon!$I$2:$I$4229,">="&F$3)+COUNTIFS(Canon!$G$2:$G$4229,"*"&$A24&"*",Canon!$H$2:$H$4229,"<"&F$4,Canon!$I$2:$I$4229,"") -> 10 | G24: =COUNTIFS(Canon!$G$2:$G$4229,"*"&$A24&"*",Canon!$H$2:$H$4229,"<"&G$4,Canon!$I$2:$I$4229,">="&G$3)+COUNTIFS(Canon!$G$2:$G$4229,"*"&$A24&"*",Canon!$H$2:$H$4229,"<"&G$4,Canon!$I$2:$I$4229,"") -> 15 | H24: =COUNTIFS(Canon!$G$2:$G$4229,"*"&$A24&"*",Canon!$H$2:$H$4229,"<"&H$4,Canon!$I$2:$I$4229,">="&H$3)+COUNTIFS(Canon!$G$2:$G$4229,"*"&$A24&"*",Canon!$H$2:$H$4229,"<"&H$4,Canon!$I$2:$I$4229,"") -> 22 | I24: =COUNTIFS(Canon!$G$2:$G$4229,"*"&$A24&"*",Canon!$H$2:$H$4229,"<"&I$4,Canon!$I$2:$I$4229,">="&I$3)+COUNTIFS(Canon!$G$2:$G$4229,"*"&$A24&"*",Canon!$H$2:$H$4229,"<"&I$4,Canon!$I$2:$I$4229,"") -> 27 | J24: =COUNTIFS(Canon!$G$2:$G$4229,"*"&$A24&"*",Canon!$H$2:$H$4229,"<"&J$4,Canon!$I$2:$I$4229,">="&J$3)+COUNTIFS(Canon!$G$2:$G$4229,"*"&$A24&"*",Canon!$H$2:$H$4229,"<"&J$4,Canon!$I$2:$I$4229,"") -> 27 | ... M24: =COUNTIFS(Canon!$G$2:$G$4229,"*"&$A24&"*",Canon!$H$2:$H$4229,"<"&M$4,Canon!$I$2:$I$4229,">="&M$3)+COUNTIFS(Canon!$G$2:$G$4229,"*"&$A24&"*",Canon!$H$2:$H$4229,"<"&M$4,Canon!$I$2:$I$4229,"") -> 25
A25: AM-LAT | B25: Colonial and modern Latin America | C25: =COUNTIFS(Canon!$G$2:$G$4229,"*"&$A25&"*",Canon!$H$2:$H$4229,"<"&C$4,Canon!$I$2:$I$4229,">="&C$3)+COUNTIFS(Canon!$G$2:$G$4229,"*"&$A25&"*",Canon!$H$2:$H$4229,"<"&C$4,Canon!$I$2:$I$4229,"") -> 0 | D25: =COUNTIFS(Canon!$G$2:$G$4229,"*"&$A25&"*",Canon!$H$2:$H$4229,"<"&D$4,Canon!$I$2:$I$4229,">="&D$3)+COUNTIFS(Canon!$G$2:$G$4229,"*"&$A25&"*",Canon!$H$2:$H$4229,"<"&D$4,Canon!$I$2:$I$4229,"") -> 1 | E25: =COUNTIFS(Canon!$G$2:$G$4229,"*"&$A25&"*",Canon!$H$2:$H$4229,"<"&E$4,Canon!$I$2:$I$4229,">="&E$3)+COUNTIFS(Canon!$G$2:$G$4229,"*"&$A25&"*",Canon!$H$2:$H$4229,"<"&E$4,Canon!$I$2:$I$4229,"") -> 4 | F25: =COUNTIFS(Canon!$G$2:$G$4229,"*"&$A25&"*",Canon!$H$2:$H$4229,"<"&F$4,Canon!$I$2:$I$4229,">="&F$3)+COUNTIFS(Canon!$G$2:$G$4229,"*"&$A25&"*",Canon!$H$2:$H$4229,"<"&F$4,Canon!$I$2:$I$4229,"") -> 4 | G25: =COUNTIFS(Canon!$G$2:$G$4229,"*"&$A25&"*",Canon!$H$2:$H$4229,"<"&G$4,Canon!$I$2:$I$4229,">="&G$3)+COUNTIFS(Canon!$G$2:$G$4229,"*"&$A25&"*",Canon!$H$2:$H$4229,"<"&G$4,Canon!$I$2:$I$4229,"") -> 8 | H25: =COUNTIFS(Canon!$G$2:$G$4229,"*"&$A25&"*",Canon!$H$2:$H$4229,"<"&H$4,Canon!$I$2:$I$4229,">="&H$3)+COUNTIFS(Canon!$G$2:$G$4229,"*"&$A25&"*",Canon!$H$2:$H$4229,"<"&H$4,Canon!$I$2:$I$4229,"") -> 8 | I25: =COUNTIFS(Canon!$G$2:$G$4229,"*"&$A25&"*",Canon!$H$2:$H$4229,"<"&I$4,Canon!$I$2:$I$4229,">="&I$3)+COUNTIFS(Canon!$G$2:$G$4229,"*"&$A25&"*",Canon!$H$2:$H$4229,"<"&I$4,Canon!$I$2:$I$4229,"") -> 10 | J25: =COUNTIFS(Canon!$G$2:$G$4229,"*"&$A25&"*",Canon!$H$2:$H$4229,"<"&J$4,Canon!$I$2:$I$4229,">="&J$3)+COUNTIFS(Canon!$G$2:$G$4229,"*"&$A25&"*",Canon!$H$2:$H$4229,"<"&J$4,Canon!$I$2:$I$4229,"") -> 18 | ... M25: =COUNTIFS(Canon!$G$2:$G$4229,"*"&$A25&"*",Canon!$H$2:$H$4229,"<"&M$4,Canon!$I$2:$I$4229,">="&M$3)+COUNTIFS(Canon!$G$2:$G$4229,"*"&$A25&"*",Canon!$H$2:$H$4229,"<"&M$4,Canon!$I$2:$I$4229,"") -> 95 | N25: Period-region: starts 1492
A26: AS-CHN | B26: China | C26: =COUNTIFS(Canon!$G$2:$G$4229,"*"&$A26&"*",Canon!$H$2:$H$4229,"<"&C$4,Canon!$I$2:$I$4229,">="&C$3)+COUNTIFS(Canon!$G$2:$G$4229,"*"&$A26&"*",Canon!$H$2:$H$4229,"<"&C$4,Canon!$I$2:$I$4229,"") -> 10 | D26: =COUNTIFS(Canon!$G$2:$G$4229,"*"&$A26&"*",Canon!$H$2:$H$4229,"<"&D$4,Canon!$I$2:$I$4229,">="&D$3)+COUNTIFS(Canon!$G$2:$G$4229,"*"&$A26&"*",Canon!$H$2:$H$4229,"<"&D$4,Canon!$I$2:$I$4229,"") -> 30 | E26: =COUNTIFS(Canon!$G$2:$G$4229,"*"&$A26&"*",Canon!$H$2:$H$4229,"<"&E$4,Canon!$I$2:$I$4229,">="&E$3)+COUNTIFS(Canon!$G$2:$G$4229,"*"&$A26&"*",Canon!$H$2:$H$4229,"<"&E$4,Canon!$I$2:$I$4229,"") -> 54 | F26: =COUNTIFS(Canon!$G$2:$G$4229,"*"&$A26&"*",Canon!$H$2:$H$4229,"<"&F$4,Canon!$I$2:$I$4229,">="&F$3)+COUNTIFS(Canon!$G$2:$G$4229,"*"&$A26&"*",Canon!$H$2:$H$4229,"<"&F$4,Canon!$I$2:$I$4229,"") -> 75 | G26: =COUNTIFS(Canon!$G$2:$G$4229,"*"&$A26&"*",Canon!$H$2:$H$4229,"<"&G$4,Canon!$I$2:$I$4229,">="&G$3)+COUNTIFS(Canon!$G$2:$G$4229,"*"&$A26&"*",Canon!$H$2:$H$4229,"<"&G$4,Canon!$I$2:$I$4229,"") -> 118 | H26: =COUNTIFS(Canon!$G$2:$G$4229,"*"&$A26&"*",Canon!$H$2:$H$4229,"<"&H$4,Canon!$I$2:$I$4229,">="&H$3)+COUNTIFS(Canon!$G$2:$G$4229,"*"&$A26&"*",Canon!$H$2:$H$4229,"<"&H$4,Canon!$I$2:$I$4229,"") -> 120 | I26: =COUNTIFS(Canon!$G$2:$G$4229,"*"&$A26&"*",Canon!$H$2:$H$4229,"<"&I$4,Canon!$I$2:$I$4229,">="&I$3)+COUNTIFS(Canon!$G$2:$G$4229,"*"&$A26&"*",Canon!$H$2:$H$4229,"<"&I$4,Canon!$I$2:$I$4229,"") -> 154 | J26: =COUNTIFS(Canon!$G$2:$G$4229,"*"&$A26&"*",Canon!$H$2:$H$4229,"<"&J$4,Canon!$I$2:$I$4229,">="&J$3)+COUNTIFS(Canon!$G$2:$G$4229,"*"&$A26&"*",Canon!$H$2:$H$4229,"<"&J$4,Canon!$I$2:$I$4229,"") -> 183 | ... M26: =COUNTIFS(Canon!$G$2:$G$4229,"*"&$A26&"*",Canon!$H$2:$H$4229,"<"&M$4,Canon!$I$2:$I$4229,">="&M$3)+COUNTIFS(Canon!$G$2:$G$4229,"*"&$A26&"*",Canon!$H$2:$H$4229,"<"&M$4,Canon!$I$2:$I$4229,"") -> 203
A27: AS-KOR | B27: Korea | C27: =COUNTIFS(Canon!$G$2:$G$4229,"*"&$A27&"*",Canon!$H$2:$H$4229,"<"&C$4,Canon!$I$2:$I$4229,">="&C$3)+COUNTIFS(Canon!$G$2:$G$4229,"*"&$A27&"*",Canon!$H$2:$H$4229,"<"&C$4,Canon!$I$2:$I$4229,"") -> 1 | D27: =COUNTIFS(Canon!$G$2:$G$4229,"*"&$A27&"*",Canon!$H$2:$H$4229,"<"&D$4,Canon!$I$2:$I$4229,">="&D$3)+COUNTIFS(Canon!$G$2:$G$4229,"*"&$A27&"*",Canon!$H$2:$H$4229,"<"&D$4,Canon!$I$2:$I$4229,"") -> 4 | E27: =COUNTIFS(Canon!$G$2:$G$4229,"*"&$A27&"*",Canon!$H$2:$H$4229,"<"&E$4,Canon!$I$2:$I$4229,">="&E$3)+COUNTIFS(Canon!$G$2:$G$4229,"*"&$A27&"*",Canon!$H$2:$H$4229,"<"&E$4,Canon!$I$2:$I$4229,"") -> 7 | F27: =COUNTIFS(Canon!$G$2:$G$4229,"*"&$A27&"*",Canon!$H$2:$H$4229,"<"&F$4,Canon!$I$2:$I$4229,">="&F$3)+COUNTIFS(Canon!$G$2:$G$4229,"*"&$A27&"*",Canon!$H$2:$H$4229,"<"&F$4,Canon!$I$2:$I$4229,"") -> 14 | G27: =COUNTIFS(Canon!$G$2:$G$4229,"*"&$A27&"*",Canon!$H$2:$H$4229,"<"&G$4,Canon!$I$2:$I$4229,">="&G$3)+COUNTIFS(Canon!$G$2:$G$4229,"*"&$A27&"*",Canon!$H$2:$H$4229,"<"&G$4,Canon!$I$2:$I$4229,"") -> 28 | H27: =COUNTIFS(Canon!$G$2:$G$4229,"*"&$A27&"*",Canon!$H$2:$H$4229,"<"&H$4,Canon!$I$2:$I$4229,">="&H$3)+COUNTIFS(Canon!$G$2:$G$4229,"*"&$A27&"*",Canon!$H$2:$H$4229,"<"&H$4,Canon!$I$2:$I$4229,"") -> 30 | I27: =COUNTIFS(Canon!$G$2:$G$4229,"*"&$A27&"*",Canon!$H$2:$H$4229,"<"&I$4,Canon!$I$2:$I$4229,">="&I$3)+COUNTIFS(Canon!$G$2:$G$4229,"*"&$A27&"*",Canon!$H$2:$H$4229,"<"&I$4,Canon!$I$2:$I$4229,"") -> 41 | J27: =COUNTIFS(Canon!$G$2:$G$4229,"*"&$A27&"*",Canon!$H$2:$H$4229,"<"&J$4,Canon!$I$2:$I$4229,">="&J$3)+COUNTIFS(Canon!$G$2:$G$4229,"*"&$A27&"*",Canon!$H$2:$H$4229,"<"&J$4,Canon!$I$2:$I$4229,"") -> 44 | ... M27: =COUNTIFS(Canon!$G$2:$G$4229,"*"&$A27&"*",Canon!$H$2:$H$4229,"<"&M$4,Canon!$I$2:$I$4229,">="&M$3)+COUNTIFS(Canon!$G$2:$G$4229,"*"&$A27&"*",Canon!$H$2:$H$4229,"<"&M$4,Canon!$I$2:$I$4229,"") -> 53
A28: AS-JPN | B28: Japan | C28: =COUNTIFS(Canon!$G$2:$G$4229,"*"&$A28&"*",Canon!$H$2:$H$4229,"<"&C$4,Canon!$I$2:$I$4229,">="&C$3)+COUNTIFS(Canon!$G$2:$G$4229,"*"&$A28&"*",Canon!$H$2:$H$4229,"<"&C$4,Canon!$I$2:$I$4229,"") -> 12 | D28: =COUNTIFS(Canon!$G$2:$G$4229,"*"&$A28&"*",Canon!$H$2:$H$4229,"<"&D$4,Canon!$I$2:$I$4229,">="&D$3)+COUNTIFS(Canon!$G$2:$G$4229,"*"&$A28&"*",Canon!$H$2:$H$4229,"<"&D$4,Canon!$I$2:$I$4229,"") -> 18 | E28: =COUNTIFS(Canon!$G$2:$G$4229,"*"&$A28&"*",Canon!$H$2:$H$4229,"<"&E$4,Canon!$I$2:$I$4229,">="&E$3)+COUNTIFS(Canon!$G$2:$G$4229,"*"&$A28&"*",Canon!$H$2:$H$4229,"<"&E$4,Canon!$I$2:$I$4229,"") -> 24 | F28: =COUNTIFS(Canon!$G$2:$G$4229,"*"&$A28&"*",Canon!$H$2:$H$4229,"<"&F$4,Canon!$I$2:$I$4229,">="&F$3)+COUNTIFS(Canon!$G$2:$G$4229,"*"&$A28&"*",Canon!$H$2:$H$4229,"<"&F$4,Canon!$I$2:$I$4229,"") -> 26 | G28: =COUNTIFS(Canon!$G$2:$G$4229,"*"&$A28&"*",Canon!$H$2:$H$4229,"<"&G$4,Canon!$I$2:$I$4229,">="&G$3)+COUNTIFS(Canon!$G$2:$G$4229,"*"&$A28&"*",Canon!$H$2:$H$4229,"<"&G$4,Canon!$I$2:$I$4229,"") -> 35 | H28: =COUNTIFS(Canon!$G$2:$G$4229,"*"&$A28&"*",Canon!$H$2:$H$4229,"<"&H$4,Canon!$I$2:$I$4229,">="&H$3)+COUNTIFS(Canon!$G$2:$G$4229,"*"&$A28&"*",Canon!$H$2:$H$4229,"<"&H$4,Canon!$I$2:$I$4229,"") -> 38 | I28: =COUNTIFS(Canon!$G$2:$G$4229,"*"&$A28&"*",Canon!$H$2:$H$4229,"<"&I$4,Canon!$I$2:$I$4229,">="&I$3)+COUNTIFS(Canon!$G$2:$G$4229,"*"&$A28&"*",Canon!$H$2:$H$4229,"<"&I$4,Canon!$I$2:$I$4229,"") -> 61 | J28: =COUNTIFS(Canon!$G$2:$G$4229,"*"&$A28&"*",Canon!$H$2:$H$4229,"<"&J$4,Canon!$I$2:$I$4229,">="&J$3)+COUNTIFS(Canon!$G$2:$G$4229,"*"&$A28&"*",Canon!$H$2:$H$4229,"<"&J$4,Canon!$I$2:$I$4229,"") -> 68 | ... M28: =COUNTIFS(Canon!$G$2:$G$4229,"*"&$A28&"*",Canon!$H$2:$H$4229,"<"&M$4,Canon!$I$2:$I$4229,">="&M$3)+COUNTIFS(Canon!$G$2:$G$4229,"*"&$A28&"*",Canon!$H$2:$H$4229,"<"&M$4,Canon!$I$2:$I$4229,"") -> 127
A29: AS-SAS | B29: South Asia | C29: =COUNTIFS(Canon!$G$2:$G$4229,"*"&$A29&"*",Canon!$H$2:$H$4229,"<"&C$4,Canon!$I$2:$I$4229,">="&C$3)+COUNTIFS(Canon!$G$2:$G$4229,"*"&$A29&"*",Canon!$H$2:$H$4229,"<"&C$4,Canon!$I$2:$I$4229,"") -> 4 | D29: =COUNTIFS(Canon!$G$2:$G$4229,"*"&$A29&"*",Canon!$H$2:$H$4229,"<"&D$4,Canon!$I$2:$I$4229,">="&D$3)+COUNTIFS(Canon!$G$2:$G$4229,"*"&$A29&"*",Canon!$H$2:$H$4229,"<"&D$4,Canon!$I$2:$I$4229,"") -> 16 | E29: =COUNTIFS(Canon!$G$2:$G$4229,"*"&$A29&"*",Canon!$H$2:$H$4229,"<"&E$4,Canon!$I$2:$I$4229,">="&E$3)+COUNTIFS(Canon!$G$2:$G$4229,"*"&$A29&"*",Canon!$H$2:$H$4229,"<"&E$4,Canon!$I$2:$I$4229,"") -> 49 | F29: =COUNTIFS(Canon!$G$2:$G$4229,"*"&$A29&"*",Canon!$H$2:$H$4229,"<"&F$4,Canon!$I$2:$I$4229,">="&F$3)+COUNTIFS(Canon!$G$2:$G$4229,"*"&$A29&"*",Canon!$H$2:$H$4229,"<"&F$4,Canon!$I$2:$I$4229,"") -> 61 | G29: =COUNTIFS(Canon!$G$2:$G$4229,"*"&$A29&"*",Canon!$H$2:$H$4229,"<"&G$4,Canon!$I$2:$I$4229,">="&G$3)+COUNTIFS(Canon!$G$2:$G$4229,"*"&$A29&"*",Canon!$H$2:$H$4229,"<"&G$4,Canon!$I$2:$I$4229,"") -> 90 | H29: =COUNTIFS(Canon!$G$2:$G$4229,"*"&$A29&"*",Canon!$H$2:$H$4229,"<"&H$4,Canon!$I$2:$I$4229,">="&H$3)+COUNTIFS(Canon!$G$2:$G$4229,"*"&$A29&"*",Canon!$H$2:$H$4229,"<"&H$4,Canon!$I$2:$I$4229,"") -> 93 | I29: =COUNTIFS(Canon!$G$2:$G$4229,"*"&$A29&"*",Canon!$H$2:$H$4229,"<"&I$4,Canon!$I$2:$I$4229,">="&I$3)+COUNTIFS(Canon!$G$2:$G$4229,"*"&$A29&"*",Canon!$H$2:$H$4229,"<"&I$4,Canon!$I$2:$I$4229,"") -> 114 | J29: =COUNTIFS(Canon!$G$2:$G$4229,"*"&$A29&"*",Canon!$H$2:$H$4229,"<"&J$4,Canon!$I$2:$I$4229,">="&J$3)+COUNTIFS(Canon!$G$2:$G$4229,"*"&$A29&"*",Canon!$H$2:$H$4229,"<"&J$4,Canon!$I$2:$I$4229,"") -> 138 | ... M29: =COUNTIFS(Canon!$G$2:$G$4229,"*"&$A29&"*",Canon!$H$2:$H$4229,"<"&M$4,Canon!$I$2:$I$4229,">="&M$3)+COUNTIFS(Canon!$G$2:$G$4229,"*"&$A29&"*",Canon!$H$2:$H$4229,"<"&M$4,Canon!$I$2:$I$4229,"") -> 222
A30: AS-HIM | B30: Himalaya and Tibet | C30: =COUNTIFS(Canon!$G$2:$G$4229,"*"&$A30&"*",Canon!$H$2:$H$4229,"<"&C$4,Canon!$I$2:$I$4229,">="&C$3)+COUNTIFS(Canon!$G$2:$G$4229,"*"&$A30&"*",Canon!$H$2:$H$4229,"<"&C$4,Canon!$I$2:$I$4229,"") -> 0 | D30: =COUNTIFS(Canon!$G$2:$G$4229,"*"&$A30&"*",Canon!$H$2:$H$4229,"<"&D$4,Canon!$I$2:$I$4229,">="&D$3)+COUNTIFS(Canon!$G$2:$G$4229,"*"&$A30&"*",Canon!$H$2:$H$4229,"<"&D$4,Canon!$I$2:$I$4229,"") -> 1 | E30: =COUNTIFS(Canon!$G$2:$G$4229,"*"&$A30&"*",Canon!$H$2:$H$4229,"<"&E$4,Canon!$I$2:$I$4229,">="&E$3)+COUNTIFS(Canon!$G$2:$G$4229,"*"&$A30&"*",Canon!$H$2:$H$4229,"<"&E$4,Canon!$I$2:$I$4229,"") -> 6 | F30: =COUNTIFS(Canon!$G$2:$G$4229,"*"&$A30&"*",Canon!$H$2:$H$4229,"<"&F$4,Canon!$I$2:$I$4229,">="&F$3)+COUNTIFS(Canon!$G$2:$G$4229,"*"&$A30&"*",Canon!$H$2:$H$4229,"<"&F$4,Canon!$I$2:$I$4229,"") -> 7 | G30: =COUNTIFS(Canon!$G$2:$G$4229,"*"&$A30&"*",Canon!$H$2:$H$4229,"<"&G$4,Canon!$I$2:$I$4229,">="&G$3)+COUNTIFS(Canon!$G$2:$G$4229,"*"&$A30&"*",Canon!$H$2:$H$4229,"<"&G$4,Canon!$I$2:$I$4229,"") -> 7 | H30: =COUNTIFS(Canon!$G$2:$G$4229,"*"&$A30&"*",Canon!$H$2:$H$4229,"<"&H$4,Canon!$I$2:$I$4229,">="&H$3)+COUNTIFS(Canon!$G$2:$G$4229,"*"&$A30&"*",Canon!$H$2:$H$4229,"<"&H$4,Canon!$I$2:$I$4229,"") -> 12 | I30: =COUNTIFS(Canon!$G$2:$G$4229,"*"&$A30&"*",Canon!$H$2:$H$4229,"<"&I$4,Canon!$I$2:$I$4229,">="&I$3)+COUNTIFS(Canon!$G$2:$G$4229,"*"&$A30&"*",Canon!$H$2:$H$4229,"<"&I$4,Canon!$I$2:$I$4229,"") -> 26 | J30: =COUNTIFS(Canon!$G$2:$G$4229,"*"&$A30&"*",Canon!$H$2:$H$4229,"<"&J$4,Canon!$I$2:$I$4229,">="&J$3)+COUNTIFS(Canon!$G$2:$G$4229,"*"&$A30&"*",Canon!$H$2:$H$4229,"<"&J$4,Canon!$I$2:$I$4229,"") -> 29 | ... M30: =COUNTIFS(Canon!$G$2:$G$4229,"*"&$A30&"*",Canon!$H$2:$H$4229,"<"&M$4,Canon!$I$2:$I$4229,">="&M$3)+COUNTIFS(Canon!$G$2:$G$4229,"*"&$A30&"*",Canon!$H$2:$H$4229,"<"&M$4,Canon!$I$2:$I$4229,"") -> 37 | N30: B01: Denisovan presence on the Tibetan Plateau (Baishiya Karst Cave) is a candidate node
A31: AS-MSE | B31: Mainland Southeast Asia | C31: =COUNTIFS(Canon!$G$2:$G$4229,"*"&$A31&"*",Canon!$H$2:$H$4229,"<"&C$4,Canon!$I$2:$I$4229,">="&C$3)+COUNTIFS(Canon!$G$2:$G$4229,"*"&$A31&"*",Canon!$H$2:$H$4229,"<"&C$4,Canon!$I$2:$I$4229,"") -> 2 | D31: =COUNTIFS(Canon!$G$2:$G$4229,"*"&$A31&"*",Canon!$H$2:$H$4229,"<"&D$4,Canon!$I$2:$I$4229,">="&D$3)+COUNTIFS(Canon!$G$2:$G$4229,"*"&$A31&"*",Canon!$H$2:$H$4229,"<"&D$4,Canon!$I$2:$I$4229,"") -> 8 | E31: =COUNTIFS(Canon!$G$2:$G$4229,"*"&$A31&"*",Canon!$H$2:$H$4229,"<"&E$4,Canon!$I$2:$I$4229,">="&E$3)+COUNTIFS(Canon!$G$2:$G$4229,"*"&$A31&"*",Canon!$H$2:$H$4229,"<"&E$4,Canon!$I$2:$I$4229,"") -> 15 | F31: =COUNTIFS(Canon!$G$2:$G$4229,"*"&$A31&"*",Canon!$H$2:$H$4229,"<"&F$4,Canon!$I$2:$I$4229,">="&F$3)+COUNTIFS(Canon!$G$2:$G$4229,"*"&$A31&"*",Canon!$H$2:$H$4229,"<"&F$4,Canon!$I$2:$I$4229,"") -> 20 | G31: =COUNTIFS(Canon!$G$2:$G$4229,"*"&$A31&"*",Canon!$H$2:$H$4229,"<"&G$4,Canon!$I$2:$I$4229,">="&G$3)+COUNTIFS(Canon!$G$2:$G$4229,"*"&$A31&"*",Canon!$H$2:$H$4229,"<"&G$4,Canon!$I$2:$I$4229,"") -> 39 | H31: =COUNTIFS(Canon!$G$2:$G$4229,"*"&$A31&"*",Canon!$H$2:$H$4229,"<"&H$4,Canon!$I$2:$I$4229,">="&H$3)+COUNTIFS(Canon!$G$2:$G$4229,"*"&$A31&"*",Canon!$H$2:$H$4229,"<"&H$4,Canon!$I$2:$I$4229,"") -> 52 | I31: =COUNTIFS(Canon!$G$2:$G$4229,"*"&$A31&"*",Canon!$H$2:$H$4229,"<"&I$4,Canon!$I$2:$I$4229,">="&I$3)+COUNTIFS(Canon!$G$2:$G$4229,"*"&$A31&"*",Canon!$H$2:$H$4229,"<"&I$4,Canon!$I$2:$I$4229,"") -> 59 | J31: =COUNTIFS(Canon!$G$2:$G$4229,"*"&$A31&"*",Canon!$H$2:$H$4229,"<"&J$4,Canon!$I$2:$I$4229,">="&J$3)+COUNTIFS(Canon!$G$2:$G$4229,"*"&$A31&"*",Canon!$H$2:$H$4229,"<"&J$4,Canon!$I$2:$I$4229,"") -> 64 | ... M31: =COUNTIFS(Canon!$G$2:$G$4229,"*"&$A31&"*",Canon!$H$2:$H$4229,"<"&M$4,Canon!$I$2:$I$4229,">="&M$3)+COUNTIFS(Canon!$G$2:$G$4229,"*"&$A31&"*",Canon!$H$2:$H$4229,"<"&M$4,Canon!$I$2:$I$4229,"") -> 55
A32: AS-ISE | B32: Island Southeast Asia | C32: =COUNTIFS(Canon!$G$2:$G$4229,"*"&$A32&"*",Canon!$H$2:$H$4229,"<"&C$4,Canon!$I$2:$I$4229,">="&C$3)+COUNTIFS(Canon!$G$2:$G$4229,"*"&$A32&"*",Canon!$H$2:$H$4229,"<"&C$4,Canon!$I$2:$I$4229,"") -> 6 | D32: =COUNTIFS(Canon!$G$2:$G$4229,"*"&$A32&"*",Canon!$H$2:$H$4229,"<"&D$4,Canon!$I$2:$I$4229,">="&D$3)+COUNTIFS(Canon!$G$2:$G$4229,"*"&$A32&"*",Canon!$H$2:$H$4229,"<"&D$4,Canon!$I$2:$I$4229,"") -> 12 | E32: =COUNTIFS(Canon!$G$2:$G$4229,"*"&$A32&"*",Canon!$H$2:$H$4229,"<"&E$4,Canon!$I$2:$I$4229,">="&E$3)+COUNTIFS(Canon!$G$2:$G$4229,"*"&$A32&"*",Canon!$H$2:$H$4229,"<"&E$4,Canon!$I$2:$I$4229,"") -> 19 | F32: =COUNTIFS(Canon!$G$2:$G$4229,"*"&$A32&"*",Canon!$H$2:$H$4229,"<"&F$4,Canon!$I$2:$I$4229,">="&F$3)+COUNTIFS(Canon!$G$2:$G$4229,"*"&$A32&"*",Canon!$H$2:$H$4229,"<"&F$4,Canon!$I$2:$I$4229,"") -> 20 | G32: =COUNTIFS(Canon!$G$2:$G$4229,"*"&$A32&"*",Canon!$H$2:$H$4229,"<"&G$4,Canon!$I$2:$I$4229,">="&G$3)+COUNTIFS(Canon!$G$2:$G$4229,"*"&$A32&"*",Canon!$H$2:$H$4229,"<"&G$4,Canon!$I$2:$I$4229,"") -> 30 | H32: =COUNTIFS(Canon!$G$2:$G$4229,"*"&$A32&"*",Canon!$H$2:$H$4229,"<"&H$4,Canon!$I$2:$I$4229,">="&H$3)+COUNTIFS(Canon!$G$2:$G$4229,"*"&$A32&"*",Canon!$H$2:$H$4229,"<"&H$4,Canon!$I$2:$I$4229,"") -> 36 | I32: =COUNTIFS(Canon!$G$2:$G$4229,"*"&$A32&"*",Canon!$H$2:$H$4229,"<"&I$4,Canon!$I$2:$I$4229,">="&I$3)+COUNTIFS(Canon!$G$2:$G$4229,"*"&$A32&"*",Canon!$H$2:$H$4229,"<"&I$4,Canon!$I$2:$I$4229,"") -> 49 | J32: =COUNTIFS(Canon!$G$2:$G$4229,"*"&$A32&"*",Canon!$H$2:$H$4229,"<"&J$4,Canon!$I$2:$I$4229,">="&J$3)+COUNTIFS(Canon!$G$2:$G$4229,"*"&$A32&"*",Canon!$H$2:$H$4229,"<"&J$4,Canon!$I$2:$I$4229,"") -> 51 | ... M32: =COUNTIFS(Canon!$G$2:$G$4229,"*"&$A32&"*",Canon!$H$2:$H$4229,"<"&M$4,Canon!$I$2:$I$4229,">="&M$3)+COUNTIFS(Canon!$G$2:$G$4229,"*"&$A32&"*",Canon!$H$2:$H$4229,"<"&M$4,Canon!$I$2:$I$4229,"") -> 74
A33: AS-CEN | B33: Central Asia and the steppe | C33: =COUNTIFS(Canon!$G$2:$G$4229,"*"&$A33&"*",Canon!$H$2:$H$4229,"<"&C$4,Canon!$I$2:$I$4229,">="&C$3)+COUNTIFS(Canon!$G$2:$G$4229,"*"&$A33&"*",Canon!$H$2:$H$4229,"<"&C$4,Canon!$I$2:$I$4229,"") -> 3 | D33: =COUNTIFS(Canon!$G$2:$G$4229,"*"&$A33&"*",Canon!$H$2:$H$4229,"<"&D$4,Canon!$I$2:$I$4229,">="&D$3)+COUNTIFS(Canon!$G$2:$G$4229,"*"&$A33&"*",Canon!$H$2:$H$4229,"<"&D$4,Canon!$I$2:$I$4229,"") -> 4 | E33: =COUNTIFS(Canon!$G$2:$G$4229,"*"&$A33&"*",Canon!$H$2:$H$4229,"<"&E$4,Canon!$I$2:$I$4229,">="&E$3)+COUNTIFS(Canon!$G$2:$G$4229,"*"&$A33&"*",Canon!$H$2:$H$4229,"<"&E$4,Canon!$I$2:$I$4229,"") -> 19 | F33: =COUNTIFS(Canon!$G$2:$G$4229,"*"&$A33&"*",Canon!$H$2:$H$4229,"<"&F$4,Canon!$I$2:$I$4229,">="&F$3)+COUNTIFS(Canon!$G$2:$G$4229,"*"&$A33&"*",Canon!$H$2:$H$4229,"<"&F$4,Canon!$I$2:$I$4229,"") -> 28 | G33: =COUNTIFS(Canon!$G$2:$G$4229,"*"&$A33&"*",Canon!$H$2:$H$4229,"<"&G$4,Canon!$I$2:$I$4229,">="&G$3)+COUNTIFS(Canon!$G$2:$G$4229,"*"&$A33&"*",Canon!$H$2:$H$4229,"<"&G$4,Canon!$I$2:$I$4229,"") -> 61 | H33: =COUNTIFS(Canon!$G$2:$G$4229,"*"&$A33&"*",Canon!$H$2:$H$4229,"<"&H$4,Canon!$I$2:$I$4229,">="&H$3)+COUNTIFS(Canon!$G$2:$G$4229,"*"&$A33&"*",Canon!$H$2:$H$4229,"<"&H$4,Canon!$I$2:$I$4229,"") -> 57 | I33: =COUNTIFS(Canon!$G$2:$G$4229,"*"&$A33&"*",Canon!$H$2:$H$4229,"<"&I$4,Canon!$I$2:$I$4229,">="&I$3)+COUNTIFS(Canon!$G$2:$G$4229,"*"&$A33&"*",Canon!$H$2:$H$4229,"<"&I$4,Canon!$I$2:$I$4229,"") -> 75 | J33: =COUNTIFS(Canon!$G$2:$G$4229,"*"&$A33&"*",Canon!$H$2:$H$4229,"<"&J$4,Canon!$I$2:$I$4229,">="&J$3)+COUNTIFS(Canon!$G$2:$G$4229,"*"&$A33&"*",Canon!$H$2:$H$4229,"<"&J$4,Canon!$I$2:$I$4229,"") -> 83 | ... M33: =COUNTIFS(Canon!$G$2:$G$4229,"*"&$A33&"*",Canon!$H$2:$H$4229,"<"&M$4,Canon!$I$2:$I$4229,">="&M$3)+COUNTIFS(Canon!$G$2:$G$4229,"*"&$A33&"*",Canon!$H$2:$H$4229,"<"&M$4,Canon!$I$2:$I$4229,"") -> 88
